<?xml version="1.0"?>
<robot
  name="test">
  <link
    name="base_link">
    <inertial>
      <origin
        xyz="0.135454608912068 -0.254330578207179 0.19184296731081"
        rpy="0 0 0" />
      <mass
        value="0.896698981932657" />
      <inertia
        ixx="0.00477033286145432"
        ixy="-1.09784258929473E-06"
        ixz="9.96523019987134E-07"
        iyy="0.00587551915336671"
        iyz="3.87423949994858E-06"
        izz="0.00937782568031088" />
    </inertial>
    <visual>
      <origin
        xyz="0 0 0"
        rpy="0 0 0" />
      <geometry>
        <mesh
          filename="package://robotont_description/meshes/base_link.STL" />
      </geometry>
      <material
        name="">
        <color
          rgba="1 1 1 1" />
      </material>
    </visual>
    <collision>
      <origin
        xyz="0 0 0"
        rpy="0 0 0" />
      <geometry>
        <mesh
          filename="package://robotont_description/meshes/base_link.STL" />
      </geometry>
    </collision>
  </link>
  <link
    name="Omniwheel1">
    <inertial>
      <origin
        xyz="5.51113170932371E-08 6.17646006839667E-07 -9.66083362752279E-08"
        rpy="0 0 0" />
      <mass
        value="0.0224355329965772" />
      <inertia
        ixx="5.90693784127277E-06"
        ixy="2.47484572726089E-10"
        ixz="4.4624205190751E-11"
        iyy="5.90478833236192E-06"
        iyz="1.76931517153296E-10"
        izz="1.03011794339244E-05" />
    </inertial>
    <visual>
      <origin
        xyz="0 0 0"
        rpy="0 0 0" />
      <geometry>
        <mesh
          filename="package://robotont_description/meshes/Omniwheel1.STL" />
      </geometry>
      <material
        name="">
        <color
          rgba="0.792156862745098 0.819607843137255 0.933333333333333 1" />
      </material>
    </visual>
    <collision>
      <origin
        xyz="0 0 0"
        rpy="0 0 0" />
      <geometry>
        <mesh
          filename="package://robotont_description/meshes/Omniwheel1.STL" />
      </geometry>
    </collision>
  </link>
  <joint
    name="Axle1"
    type="continuous">
    <origin
      xyz="0.022326481506329 -0.176779457314387 0.182850551353376"
      rpy="1.5707963267949 0.836473203822852 -2.09439510239319" />
    <parent
      link="base_link" />
    <child
      link="Omniwheel1" />
    <axis
      xyz="0 0 -1" />
  </joint>
  <link
    name="Roller11">
    <inertial>
      <origin
        xyz="0.0090562476933763 -6.24358922374224E-06 2.4370655343775E-07"
        rpy="0 0 0" />
      <mass
        value="0.00222805970857661" />
      <inertia
        ixx="6.29206948993392E-08"
        ixy="4.88962427812512E-13"
        ixz="3.19630145455555E-12"
        iyy="8.63043199686779E-08"
        iyz="6.68903337025076E-13"
        izz="8.63116179634987E-08" />
    </inertial>
    <visual>
      <origin
        xyz="0 0 0"
        rpy="0 0 0" />
      <geometry>
        <mesh
          filename="package://robotont_description/meshes/Roller11.STL" />
      </geometry>
      <material
        name="">
        <color
          rgba="0.792156862745098 0.819607843137255 0.933333333333333 1" />
      </material>
    </visual>
    <collision>
      <origin
        xyz="0 0 0"
        rpy="0 0 0" />
      <geometry>
        <mesh
          filename="package://robotont_description/meshes/Roller11.STL" />
      </geometry>
    </collision>
  </link>
  <joint
    name="Roller11"
    type="continuous">
    <origin
      xyz="-0.00905600884677152 0.0275059261982972 0.00800224940532278"
      rpy="0.362770953244145 -2.22044604925031E-16 1.0547118733939E-15" />
    <parent
      link="Omniwheel1" />
    <child
      link="Roller11" />
    <axis
      xyz="-1 0 0" />
  </joint>
  <link
    name="Roller12">
    <inertial>
      <origin
        xyz="0.00905625003048635 -6.24642743179971E-06 7.53208425380292E-07"
        rpy="0 0 0" />
      <mass
        value="0.00222805300985277" />
      <inertia
        ixx="6.29215432528039E-08"
        ixy="5.17309284687423E-13"
        ixz="2.31231138228572E-12"
        iyy="8.63038695173611E-08"
        iyz="7.08851473534721E-13"
        izz="8.63126289968283E-08" />
    </inertial>
    <visual>
      <origin
        xyz="0 0 0"
        rpy="0 0 0" />
      <geometry>
        <mesh
          filename="package://robotont_description/meshes/Roller12.STL" />
      </geometry>
      <material
        name="">
        <color
          rgba="0.792156862745098 0.819607843137255 0.933333333333333 1" />
      </material>
    </visual>
    <collision>
      <origin
        xyz="0 0 0"
        rpy="0 0 0" />
      <geometry>
        <mesh
          filename="package://robotont_description/meshes/Roller12.STL" />
      </geometry>
    </collision>
  </link>
  <joint
    name="Roller12"
    type="continuous">
    <origin
      xyz="0.0158586698947665 0.0242299372972322 0.00800224940532278"
      rpy="0.362770953711663 4.96327464162194E-05 -0.897579061938864" />
    <parent
      link="Omniwheel1" />
    <child
      link="Roller12" />
    <axis
      xyz="-0.99999999859084 0 -5.30878583583499E-05" />
  </joint>
  <link
    name="Roller13">
    <inertial>
      <origin
        xyz="0.00905624899799087 -6.24372596449985E-06 6.5074332976367E-07"
        rpy="0 0 0" />
      <mass
        value="0.00222805817486766" />
      <inertia
        ixx="6.2920956704011E-08"
        ixy="4.92440082823917E-13"
        ixz="2.2075654857175E-12"
        iyy="8.63043189882584E-08"
        iyz="6.78768649134798E-13"
        izz="8.63118155685825E-08" />
    </inertial>
    <visual>
      <origin
        xyz="0 0 0"
        rpy="0 0 0" />
      <geometry>
        <mesh
          filename="package://robotont_description/meshes/Roller13.STL" />
      </geometry>
      <material
        name="">
        <color
          rgba="0.792156862745098 0.819607843137255 0.933333333333333 1" />
      </material>
    </visual>
    <collision>
      <origin
        xyz="0 0 0"
        rpy="0 0 0" />
      <geometry>
        <mesh
          filename="package://robotont_description/meshes/Roller13.STL" />
      </geometry>
    </collision>
  </link>
  <joint
    name="Roller13"
    type="continuous">
    <origin
      xyz="0.0288314467476335 0.00270831141070441 0.00800224940532276"
      rpy="0.362770953568811 4.136062353274E-05 -1.79518010281175" />
    <parent
      link="Omniwheel1" />
    <child
      link="Roller13" />
    <axis
      xyz="-0.999999999021416 0 -4.42398835954205E-05" />
  </joint>
  <link
    name="Roller14">
    <inertial>
      <origin
        xyz="0.00905624982969072 -6.24595132203698E-06 6.17445233580538E-07"
        rpy="0 0 0" />
      <mass
        value="0.00222804814526446" />
      <inertia
        ixx="6.2922151464818E-08"
        ixy="5.00883276809346E-13"
        ixz="2.98267698300251E-12"
        iyy="8.63035277887356E-08"
        iyz="7.65745141657323E-13"
        izz="8.6313410072764E-08" />
    </inertial>
    <visual>
      <origin
        xyz="0 0 0"
        rpy="0 0 0" />
      <geometry>
        <mesh
          filename="package://robotont_description/meshes/Roller14.STL" />
      </geometry>
      <material
        name="">
        <color
          rgba="0.792156862745098 0.819607843137255 0.933333333333333 1" />
      </material>
    </visual>
    <collision>
      <origin
        xyz="0 0 0"
        rpy="0 0 0" />
      <geometry>
        <mesh
          filename="package://robotont_description/meshes/Roller14.STL" />
      </geometry>
    </collision>
  </link>
  <joint
    name="Roller14"
    type="continuous">
    <origin
      xyz="0.0200935561451987 -0.0208527282075686 0.00800224940532276"
      rpy="0.36277095345193 3.30884973664274E-05 -2.69278114368587" />
    <parent
      link="Omniwheel1" />
    <child
      link="Roller14" />
    <axis
      xyz="0.999999999373706 0 3.53919053181495E-05" />
  </joint>
  <link
    name="Roller15">
    <inertial>
      <origin
        xyz="0.00905624987976852 -6.24513404964833E-06 4.87126271431215E-07"
        rpy="0 0 0" />
      <mass
        value="0.00222805836001247" />
      <inertia
        ixx="6.29209661808733E-08"
        ixy="6.21947992051887E-13"
        ixz="2.61039403778903E-12"
        iyy="8.6304315415605E-08"
        iyz="8.09887301604748E-13"
        izz="8.63117986071289E-08" />
    </inertial>
    <visual>
      <origin
        xyz="0 0 0"
        rpy="0 0 0" />
      <geometry>
        <mesh
          filename="package://robotont_description/meshes/Roller15.STL" />
      </geometry>
      <material
        name="">
        <color
          rgba="0.792156862745098 0.819607843137255 0.933333333333333 1" />
      </material>
    </visual>
    <collision>
      <origin
        xyz="0 0 0"
        rpy="0 0 0" />
      <geometry>
        <mesh
          filename="package://robotont_description/meshes/Roller15.STL" />
      </geometry>
    </collision>
  </link>
  <joint
    name="Roller15"
    type="continuous">
    <origin
      xyz="-0.00377519206841899 -0.0287112381674063 0.00800224940532274"
      rpy="0.362770953361024 2.48163744035266E-05 2.6928031226208" />
    <parent
      link="Omniwheel1" />
    <child
      link="Roller15" />
    <axis
      xyz="0.99999999964771 0 2.65439304654308E-05" />
  </joint>
  <link
    name="Roller16">
    <inertial>
      <origin
        xyz="0.00905625171281951 -6.24549699594634E-06 4.67055512903825E-07"
        rpy="0 0 0" />
      <mass
        value="0.00222804542902184" />
      <inertia
        ixx="6.29227702499175E-08"
        ixy="4.97216980945624E-13"
        ixz="3.4246678879344E-12"
        iyy="8.63036751661587E-08"
        iyz="7.99146560214892E-13"
        izz="8.63137764245749E-08" />
    </inertial>
    <visual>
      <origin
        xyz="0 0 0"
        rpy="0 0 0" />
      <geometry>
        <mesh
          filename="package://robotont_description/meshes/Roller16.STL" />
      </geometry>
      <material
        name="">
        <color
          rgba="0.792156862745098 0.819607843137255 0.933333333333333 1" />
      </material>
    </visual>
    <collision>
      <origin
        xyz="0 0 0"
        rpy="0 0 0" />
      <geometry>
        <mesh
          filename="package://robotont_description/meshes/Roller16.STL" />
      </geometry>
    </collision>
  </link>
  <joint
    name="Roller16"
    type="continuous">
    <origin
      xyz="-0.0248011436546332 -0.0149496001846614 0.00800224940532276"
      rpy="0.362770953296091 1.65442494603261E-05 1.79520208174714" />
    <parent
      link="Omniwheel1" />
    <child
      link="Roller16" />
    <axis
      xyz="0.999999999843426 0 1.76959534931714E-05" />
  </joint>
  <link
    name="Roller17">
    <inertial>
      <origin
        xyz="0.00905624714251091 -6.24411402405656E-06 3.31840344425238E-07"
        rpy="0 0 0" />
      <mass
        value="0.00222805825576709" />
      <inertia
        ixx="6.29207927439633E-08"
        ixy="5.05419677413105E-13"
        ixz="3.13865668059066E-12"
        iyy="8.63040811412927E-08"
        iyz="7.29478493580458E-13"
        izz="8.63119038700248E-08" />
    </inertial>
    <visual>
      <origin
        xyz="0 0 0"
        rpy="0 0 0" />
      <geometry>
        <mesh
          filename="package://robotont_description/meshes/Roller17.STL" />
      </geometry>
      <material
        name="">
        <color
          rgba="0.792156862745098 0.819607843137255 0.933333333333333 1" />
      </material>
    </visual>
    <collision>
      <origin
        xyz="0 0 0"
        rpy="0 0 0" />
      <geometry>
        <mesh
          filename="package://robotont_description/meshes/Roller17.STL" />
      </geometry>
    </collision>
  </link>
  <joint
    name="Roller17"
    type="continuous">
    <origin
      xyz="-0.0271513282177754 0.0100693916534027 0.00800224940532278"
      rpy="0.362770953257132 8.27212416175113E-06 0.897601040873349" />
    <parent
      link="Omniwheel1" />
    <child
      link="Roller17" />
    <axis
      xyz="-0.222517872822441 0.911476772960516 -0.345970936103106" />
  </joint>
  <link
    name="Roller18">
    <inertial>
      <origin
        xyz="0.00905625145856824 -6.24761901268922E-06 1.0163672875263E-06"
        rpy="0 0 0" />
      <mass
        value="0.00222804667573871" />
      <inertia
        ixx="6.29224688547726E-08"
        ixy="5.17012520909878E-13"
        ixz="1.97593000955424E-12"
        iyy="8.63035856870094E-08"
        iyz="7.59631533987743E-13"
        izz="8.63135844877172E-08" />
    </inertial>
    <visual>
      <origin
        xyz="0 0 0"
        rpy="0 0 0" />
      <geometry>
        <mesh
          filename="package://robotont_description/meshes/Roller18.STL" />
      </geometry>
      <material
        name="">
        <color
          rgba="0.792156862745098 0.819607843137255 0.933333333333333 1" />
      </material>
    </visual>
    <collision>
      <origin
        xyz="0 0 0"
        rpy="0 0 0" />
      <geometry>
        <mesh
          filename="package://robotont_description/meshes/Roller18.STL" />
      </geometry>
    </collision>
  </link>
  <joint
    name="Roller18"
    type="continuous">
    <origin
      xyz="-0.00377094534323913 0.0287024197517056 -0.00799497322847986"
      rpy="0.915756260970597 4.81813406636344E-05 -2.69273098229598" />
    <parent
      link="Omniwheel1" />
    <child
      link="Roller18" />
    <axis
      xyz="0.999999996872331 0 7.90906943926584E-05" />
  </joint>
  <link
    name="Roller19">
    <inertial>
      <origin
        xyz="0.00905625100119239 -6.24603636639742E-06 7.84478363977104E-07"
        rpy="0 0 0" />
      <mass
        value="0.00222805805773092" />
      <inertia
        ixx="6.29210768819761E-08"
        ixy="5.50551055703456E-13"
        ixz="1.81992887215392E-12"
        iyy="8.63044063542196E-08"
        iyz="7.21834398562332E-13"
        izz="8.63117964118533E-08" />
    </inertial>
    <visual>
      <origin
        xyz="0 0 0"
        rpy="0 0 0" />
      <geometry>
        <mesh
          filename="package://robotont_description/meshes/Roller19.STL" />
      </geometry>
      <material
        name="">
        <color
          rgba="0.792156862745098 0.819607843137255 0.933333333333333 1" />
      </material>
    </visual>
    <collision>
      <origin
        xyz="0 0 0"
        rpy="0 0 0" />
      <geometry>
        <mesh
          filename="package://robotont_description/meshes/Roller19.STL" />
      </geometry>
    </collision>
  </link>
  <joint
    name="Roller19"
    type="continuous">
    <origin
      xyz="0.0200893094200195 0.0208439097918678 -0.00799497322847988"
      rpy="0.915756260309541 3.61360050554162E-05 2.69284074366209" />
    <parent
      link="Omniwheel1" />
    <child
      link="Roller19" />
    <axis
      xyz="0.999999998240686 0 5.93180200797877E-05" />
  </joint>
  <link
    name="Roller110">
    <inertial>
      <origin
        xyz="0.00905625316147435 -6.24701480489431E-06 6.53889737821378E-07"
        rpy="0 0 0" />
      <mass
        value="0.00222804736414082" />
      <inertia
        ixx="6.29226595794278E-08"
        ixy="4.5294929858025E-13"
        ixz="2.76577683882858E-12"
        iyy="8.6303969161013E-08"
        iyz="7.09513676744389E-13"
        izz="8.63134357662986E-08" />
    </inertial>
    <visual>
      <origin
        xyz="0 0 0"
        rpy="0 0 0" />
      <geometry>
        <mesh
          filename="package://robotont_description/meshes/Roller110.STL" />
      </geometry>
      <material
        name="">
        <color
          rgba="0.792156862745098 0.819607843137255 0.933333333333333 1" />
      </material>
    </visual>
    <collision>
      <origin
        xyz="0 0 0"
        rpy="0 0 0" />
      <geometry>
        <mesh
          filename="package://robotont_description/meshes/Roller110.STL" />
      </geometry>
    </collision>
  </link>
  <joint
    name="Roller110"
    type="continuous">
    <origin
      xyz="0.0288219044427726 -0.0027104893795199 -0.00799497322847986"
      rpy="0.915756259837358 2.40906703969355E-05 1.79522716244185" />
    <parent
      link="Omniwheel1" />
    <child
      link="Roller110" />
    <axis
      xyz="0.999999999218083 0 3.95453473158447E-05" />
  </joint>
  <link
    name="Roller111">
    <inertial>
      <origin
        xyz="0.00905624625161292 -6.24320986174209E-06 4.21781121529019E-07"
        rpy="0 0 0" />
      <mass
        value="0.00222806016762835" />
      <inertia
        ixx="6.29205128052935E-08"
        ixy="5.80147212656581E-13"
        ixz="2.78720535245339E-12"
        iyy="8.63041758522932E-08"
        iyz="7.96508920863276E-13"
        izz="8.63116044635527E-08" />
    </inertial>
    <visual>
      <origin
        xyz="0 0 0"
        rpy="0 0 0" />
      <geometry>
        <mesh
          filename="package://robotont_description/meshes/Roller111.STL" />
      </geometry>
      <material
        name="">
        <color
          rgba="0.792156862745098 0.819607843137255 0.933333333333333 1" />
      </material>
    </visual>
    <collision>
      <origin
        xyz="0 0 0"
        rpy="0 0 0" />
      <geometry>
        <mesh
          filename="package://robotont_description/meshes/Roller111.STL" />
      </geometry>
    </collision>
  </link>
  <joint
    name="Roller111"
    type="continuous">
    <origin
      xyz="0.0158510175604117 -0.0242238347642219 -0.00799497322847989"
      rpy="0.915756259554049 1.20453338984942E-05 0.897613581219221" />
    <parent
      link="Omniwheel1" />
    <child
      link="Roller111" />
    <axis
      xyz="0.999999999804521 0 1.97726715280566E-05" />
  </joint>
  <link
    name="Roller112">
    <inertial>
      <origin
        xyz="0.00905624618941688 -6.24394835372841E-06 2.1996671284441E-07"
        rpy="0 0 0" />
      <mass
        value="0.00222806454853658" />
      <inertia
        ixx="6.2920067448706E-08"
        ixy="5.35910979423317E-13"
        ixz="2.91645592250475E-12"
        iyy="8.63046137513935E-08"
        iyz="6.6674956740383E-13"
        izz="8.63108639696968E-08" />
    </inertial>
    <visual>
      <origin
        xyz="0 0 0"
        rpy="0 0 0" />
      <geometry>
        <mesh
          filename="package://robotont_description/meshes/Roller112.STL" />
      </geometry>
      <material
        name="">
        <color
          rgba="0.792156862745098 0.819607843137255 0.933333333333333 1" />
      </material>
    </visual>
    <collision>
      <origin
        xyz="0 0 0"
        rpy="0 0 0" />
      <geometry>
        <mesh
          filename="package://robotont_description/meshes/Roller112.STL" />
      </geometry>
    </collision>
  </link>
  <joint
    name="Roller112"
    type="continuous">
    <origin
      xyz="-0.00905600884677145 -0.0274961384952869 -0.00799497322847989"
      rpy="0.915756259459612 -2.77555756156289E-16 1.22124532708767E-15" />
    <parent
      link="Omniwheel1" />
    <child
      link="Roller112" />
    <axis
      xyz="-1 0 0" />
  </joint>
  <link
    name="Roller113">
    <inertial>
      <origin
        xyz="0.00905625195426071 -6.24661762665957E-06 2.74506474134961E-07"
        rpy="0 0 0" />
      <mass
        value="0.00222805215455413" />
      <inertia
        ixx="6.29218607574591E-08"
        ixy="5.18625747546891E-13"
        ixz="3.52160152933215E-12"
        iyy="8.6304043308765E-08"
        iyz="7.34598956848397E-13"
        izz="8.63127290887446E-08" />
    </inertial>
    <visual>
      <origin
        xyz="0 0 0"
        rpy="0 0 0" />
      <geometry>
        <mesh
          filename="package://robotont_description/meshes/Roller113.STL" />
      </geometry>
      <material
        name="">
        <color
          rgba="0.792156862745098 0.819607843137255 0.933333333333333 1" />
      </material>
    </visual>
    <collision>
      <origin
        xyz="0 0 0"
        rpy="0 0 0" />
      <geometry>
        <mesh
          filename="package://robotont_description/meshes/Roller113.STL" />
      </geometry>
    </collision>
  </link>
  <joint
    name="Roller113"
    type="continuous">
    <origin
      xyz="-0.0271436758834209 -0.0100632891203918 -0.00799497322847989"
      rpy="0.915756259459612 1.94289029309402E-16 -0.897597901025656" />
    <parent
      link="Omniwheel1" />
    <child
      link="Roller113" />
    <axis
      xyz="-1 0 0" />
  </joint>
  <link
    name="Roller114">
    <inertial>
      <origin
        xyz="0.00905625010279834 -6.24547053149072E-06 1.19126770442568E-06"
        rpy="0 0 0" />
      <mass
        value="0.00222804854629662" />
      <inertia
        ixx="6.29222349335793E-08"
        ixy="4.15827932836481E-13"
        ixz="1.42816834261541E-12"
        iyy="8.63037292804102E-08"
        iyz="6.82678252433292E-13"
        izz="8.63133359189824E-08" />
    </inertial>
    <visual>
      <origin
        xyz="0 0 0"
        rpy="0 0 0" />
      <geometry>
        <mesh
          filename="package://robotont_description/meshes/Roller114.STL" />
      </geometry>
      <material
        name="">
        <color
          rgba="0.792156862745098 0.819607843137255 0.933333333333333 1" />
      </material>
    </visual>
    <collision>
      <origin
        xyz="0 0 0"
        rpy="0 0 0" />
      <geometry>
        <mesh
          filename="package://robotont_description/meshes/Roller114.STL" />
      </geometry>
    </collision>
  </link>
  <joint
    name="Roller114"
    type="continuous">
    <origin
      xyz="-0.024791601349772 0.0149474222158465 -0.00799497322847989"
      rpy="0.915756261820527 6.02266757044277E-05 -1.79511740107518" />
    <parent
      link="Omniwheel1" />
    <child
      link="Roller114" />
    <axis
      xyz="-0.999999995113017 0 -9.88633677644346E-05" />
  </joint>
  <link
    name="Omniwheel2">
    <inertial>
      <origin
        xyz="5.41212678006886E-08 6.17218780779583E-07 -9.69348333268449E-08"
        rpy="0 0 0" />
      <mass
        value="0.0224355229928124" />
      <inertia
        ixx="5.90693757523995E-06"
        ixy="2.47313010648911E-10"
        ixz="4.42240924361494E-11"
        iyy="5.90478822289202E-06"
        iyz="1.7756477578438E-10"
        izz="1.03011782727051E-05" />
    </inertial>
    <visual>
      <origin
        xyz="0 0 0"
        rpy="0 0 0" />
      <geometry>
        <mesh
          filename="package://robotont_description/meshes/Omniwheel2.STL" />
      </geometry>
      <material
        name="">
        <color
          rgba="0.792156862745098 0.819607843137255 0.933333333333333 1" />
      </material>
    </visual>
    <collision>
      <origin
        xyz="0 0 0"
        rpy="0 0 0" />
      <geometry>
        <mesh
          filename="package://robotont_description/meshes/Omniwheel2.STL" />
      </geometry>
    </collision>
  </link>
  <joint
    name="Axle2"
    type="continuous">
    <origin
      xyz="0.135408219510917 -0.372642772946523 0.182850551353376"
      rpy="1.5707963267949 0.836473203822852 -6.782769887674E-17" />
    <parent
      link="base_link" />
    <child
      link="Omniwheel2" />
    <axis
      xyz="0 0 1" />
  </joint>
  <link
    name="Roller21">
    <inertial>
      <origin
        xyz="0.00905624807800218 -6.24327273396341E-06 2.51589222177717E-07"
        rpy="0 0 0" />
      <mass
        value="0.00222805815295261" />
      <inertia
        ixx="6.29209085009669E-08"
        ixy="4.69761783118323E-13"
        ixz="3.27613725276043E-12"
        iyy="8.63042438269798E-08"
        iyz="6.688918708658E-13"
        izz="8.63118579736287E-08" />
    </inertial>
    <visual>
      <origin
        xyz="0 0 0"
        rpy="0 0 0" />
      <geometry>
        <mesh
          filename="package://robotont_description/meshes/Roller21.STL" />
      </geometry>
      <material
        name="">
        <color
          rgba="0.792156862745098 0.819607843137255 0.933333333333333 1" />
      </material>
    </visual>
    <collision>
      <origin
        xyz="0 0 0"
        rpy="0 0 0" />
      <geometry>
        <mesh
          filename="package://robotont_description/meshes/Roller21.STL" />
      </geometry>
    </collision>
  </link>
  <joint
    name="Roller21"
    type="continuous">
    <origin
      xyz="-0.00905600884677153 0.0275059261982972 0.00800224940532274"
      rpy="0.362770953244145 0 1.11022302462516E-15" />
    <parent
      link="Omniwheel2" />
    <child
      link="Roller21" />
    <axis
      xyz="-1 0 0" />
  </joint>
  <link
    name="Roller22">
    <inertial>
      <origin
        xyz="0.00905625083989886 -6.24661141984673E-06 7.53096852768032E-07"
        rpy="0 0 0" />
      <mass
        value="0.00222805285160954" />
      <inertia
        ixx="6.29216461117548E-08"
        ixy="5.08938350442107E-13"
        ixz="2.28576271572672E-12"
        iyy="8.63039608776603E-08"
        iyz="7.0106194851076E-13"
        izz="8.63126297508331E-08" />
    </inertial>
    <visual>
      <origin
        xyz="0 0 0"
        rpy="0 0 0" />
      <geometry>
        <mesh
          filename="package://robotont_description/meshes/Roller22.STL" />
      </geometry>
      <material
        name="">
        <color
          rgba="0.792156862745098 0.819607843137255 0.933333333333333 1" />
      </material>
    </visual>
    <collision>
      <origin
        xyz="0 0 0"
        rpy="0 0 0" />
      <geometry>
        <mesh
          filename="package://robotont_description/meshes/Roller22.STL" />
      </geometry>
    </collision>
  </link>
  <joint
    name="Roller22"
    type="continuous">
    <origin
      xyz="0.0158586698947665 0.0242299372972323 0.00800224940532274"
      rpy="0.362770953711663 4.96327464161286E-05 -0.897579061938864" />
    <parent
      link="Omniwheel2" />
    <child
      link="Roller22" />
    <axis
      xyz="-0.99999999859084 0 -5.30878583579128E-05" />
  </joint>
  <link
    name="Roller23">
    <inertial>
      <origin
        xyz="0.00905624721180887 -6.24211011457376E-06 6.33942279393285E-07"
        rpy="0 0 0" />
      <mass
        value="0.00222806201419234" />
      <inertia
        ixx="6.29204492785542E-08"
        ixy="5.98048210863455E-13"
        ixz="2.00513142402598E-12"
        iyy="8.63045317982439E-08"
        iyz="7.9198993407818E-13"
        izz="8.631125287325E-08" />
    </inertial>
    <visual>
      <origin
        xyz="0 0 0"
        rpy="0 0 0" />
      <geometry>
        <mesh
          filename="package://robotont_description/meshes/Roller23.STL" />
      </geometry>
      <material
        name="">
        <color
          rgba="0.792156862745098 0.819607843137255 0.933333333333333 1" />
      </material>
    </visual>
    <collision>
      <origin
        xyz="0 0 0"
        rpy="0 0 0" />
      <geometry>
        <mesh
          filename="package://robotont_description/meshes/Roller23.STL" />
      </geometry>
    </collision>
  </link>
  <joint
    name="Roller23"
    type="continuous">
    <origin
      xyz="0.0288314467476335 0.00270831141070441 0.00800224940532274"
      rpy="0.36277095356881 4.13606235323142E-05 -1.79518010281175" />
    <parent
      link="Omniwheel2" />
    <child
      link="Roller23" />
    <axis
      xyz="-0.999999999021416 0 -4.42398835952817E-05" />
  </joint>
  <link
    name="Roller24">
    <inertial>
      <origin
        xyz="0.00905625159806799 -6.24517127065238E-06 6.06707110051286E-07"
        rpy="0 0 0" />
      <mass
        value="0.00222804994084183" />
      <inertia
        ixx="6.2922151116949E-08"
        ixy="5.23614956504236E-13"
        ixz="2.81020935708934E-12"
        iyy="8.63039044385424E-08"
        iyz="7.92724737626576E-13"
        izz="8.63130949111851E-08" />
    </inertial>
    <visual>
      <origin
        xyz="0 0 0"
        rpy="0 0 0" />
      <geometry>
        <mesh
          filename="package://robotont_description/meshes/Roller24.STL" />
      </geometry>
      <material
        name="">
        <color
          rgba="0.792156862745098 0.819607843137255 0.933333333333333 1" />
      </material>
    </visual>
    <collision>
      <origin
        xyz="0 0 0"
        rpy="0 0 0" />
      <geometry>
        <mesh
          filename="package://robotont_description/meshes/Roller24.STL" />
      </geometry>
    </collision>
  </link>
  <joint
    name="Roller24"
    type="continuous">
    <origin
      xyz="0.0200935561451987 -0.0208527282075686 0.00800224940532274"
      rpy="0.362770953451931 3.30884973659497E-05 -2.69278114368587" />
    <parent
      link="Omniwheel2" />
    <child
      link="Roller24" />
    <axis
      xyz="-0.999999999373707 0 -3.53919053184271E-05" />
  </joint>
  <link
    name="Roller25">
    <inertial>
      <origin
        xyz="0.00905624986061815 -6.24502850865571E-06 4.88103026219378E-07"
        rpy="0 0 0" />
      <mass
        value="0.00222805817783925" />
      <inertia
        ixx="6.29209838185494E-08"
        ixy="6.14234058942192E-13"
        ixz="2.62100012636904E-12"
        iyy="8.63043028972297E-08"
        iyz="8.02184453816313E-13"
        izz="8.63118240867367E-08" />
    </inertial>
    <visual>
      <origin
        xyz="0 0 0"
        rpy="0 0 0" />
      <geometry>
        <mesh
          filename="package://robotont_description/meshes/Roller25.STL" />
      </geometry>
      <material
        name="">
        <color
          rgba="0.792156862745098 0.819607843137255 0.933333333333333 1" />
      </material>
    </visual>
    <collision>
      <origin
        xyz="0 0 0"
        rpy="0 0 0" />
      <geometry>
        <mesh
          filename="package://robotont_description/meshes/Roller25.STL" />
      </geometry>
    </collision>
  </link>
  <joint
    name="Roller25"
    type="continuous">
    <origin
      xyz="-0.00377519206841903 -0.0287112381674063 0.00800224940532274"
      rpy="0.362770953361025 2.48163744033955E-05 2.6928031226208" />
    <parent
      link="Omniwheel2" />
    <child
      link="Roller25" />
    <axis
      xyz="0.99999999964771 0 2.65439304655279E-05" />
  </joint>
  <link
    name="Roller26">
    <inertial>
      <origin
        xyz="0.0090563 -6.2452E-06 2.8554E-07"
        rpy="0 0 0" />
      <mass
        value="0.0022281" />
      <inertia
        ixx="6.2922E-08"
        ixy="4.8008E-13"
        ixz="3.6315E-12"
        iyy="8.6304E-08"
        iyz="7.3482E-13"
        izz="8.6313E-08" />
    </inertial>
    <visual>
      <origin
        xyz="0 0 0"
        rpy="0 0 0" />
      <geometry>
        <mesh
          filename="package://robotont_description/meshes/Roller26.STL" />
      </geometry>
      <material
        name="">
        <color
          rgba="0.79216 0.81961 0.93333 1" />
      </material>
    </visual>
    <collision>
      <origin
        xyz="0 0 0"
        rpy="0 0 0" />
      <geometry>
        <mesh
          filename="package://robotont_description/meshes/Roller26.STL" />
      </geometry>
    </collision>
  </link>
  <joint
    name="Roller26"
    type="continuous">
    <origin
      xyz="-0.0248011436546332 -0.0149496001846614 0.00800224940532274"
      rpy="0.362770953244145 2.77555756156289E-17 1.7951958020513" />
    <parent
      link="Omniwheel2" />
    <child
      link="Roller26" />
    <axis
      xyz="1 0 0" />
  </joint>
  <link
    name="Roller27">
    <inertial>
      <origin
        xyz="0.00905625075471189 -6.24757100714524E-06 3.47038065451333E-07"
        rpy="0 0 0" />
      <mass
        value="0.00222805388994341" />
      <inertia
        ixx="6.29215041116412E-08"
        ixy="5.15111747288965E-13"
        ixz="3.28232993245941E-12"
        iyy="8.63039824659597E-08"
        iyz="6.95873336494847E-13"
        izz="8.63124929490107E-08" />
    </inertial>
    <visual>
      <origin
        xyz="0 0 0"
        rpy="0 0 0" />
      <geometry>
        <mesh
          filename="package://robotont_description/meshes/Roller27.STL" />
      </geometry>
      <material
        name="">
        <color
          rgba="0.792156862745098 0.819607843137255 0.933333333333333 1" />
      </material>
    </visual>
    <collision>
      <origin
        xyz="0 0 0"
        rpy="0 0 0" />
      <geometry>
        <mesh
          filename="package://robotont_description/meshes/Roller27.STL" />
      </geometry>
    </collision>
  </link>
  <joint
    name="Roller27"
    type="continuous">
    <origin
      xyz="-0.0271513282177754 0.0100693916534027 0.00800224940532274"
      rpy="0.362770953257132 8.27212416226734E-06 0.897601040873349" />
    <parent
      link="Omniwheel2" />
    <child
      link="Roller27" />
    <axis
      xyz="0.999999999960857 0 0" />
  </joint>
  <link
    name="Roller28">
    <inertial>
      <origin
        xyz="0.00905625140304254 -6.24630847245733E-06 9.94551070887528E-07"
        rpy="0 0 0" />
      <mass
        value="0.00222805161471968" />
      <inertia
        ixx="6.29219126349323E-08"
        ixy="4.79755033475369E-13"
        ixz="1.70735424447693E-12"
        iyy="8.63039923214094E-08"
        iyz="7.03938421706699E-13"
        izz="8.63128286775647E-08" />
    </inertial>
    <visual>
      <origin
        xyz="0 0 0"
        rpy="0 0 0" />
      <geometry>
        <mesh
          filename="package://robotont_description/meshes/Roller28.STL" />
      </geometry>
      <material
        name="">
        <color
          rgba="0.792156862745098 0.819607843137255 0.933333333333333 1" />
      </material>
    </visual>
    <collision>
      <origin
        xyz="0 0 0"
        rpy="0 0 0" />
      <geometry>
        <mesh
          filename="package://robotont_description/meshes/Roller28.STL" />
      </geometry>
    </collision>
  </link>
  <joint
    name="Roller28"
    type="continuous">
    <origin
      xyz="-0.00377094534323914 0.0287024197517057 -0.00799497322847992"
      rpy="0.915756260970598 4.81813406631331E-05 -2.69273098229598" />
    <parent
      link="Omniwheel2" />
    <child
      link="Roller28" />
    <axis
      xyz="-0.999999996872331 0 -7.90906943937686E-05" />
  </joint>
  <link
    name="Roller29">
    <inertial>
      <origin
        xyz="0.00905625050590911 -6.24563281481638E-06 7.86328083202115E-07"
        rpy="0 0 0" />
      <mass
        value="0.00222805776818381" />
      <inertia
        ixx="6.29210849871572E-08"
        ixy="5.52697186729643E-13"
        ixz="1.84893575033336E-12"
        iyy="8.63043467493517E-08"
        iyz="7.26030042868793E-13"
        izz="8.63118626592299E-08" />
    </inertial>
    <visual>
      <origin
        xyz="0 0 0"
        rpy="0 0 0" />
      <geometry>
        <mesh
          filename="package://robotont_description/meshes/Roller29.STL" />
      </geometry>
      <material
        name="">
        <color
          rgba="0.792156862745098 0.819607843137255 0.933333333333333 1" />
      </material>
    </visual>
    <collision>
      <origin
        xyz="0 0 0"
        rpy="0 0 0" />
      <geometry>
        <mesh
          filename="package://robotont_description/meshes/Roller29.STL" />
      </geometry>
    </collision>
  </link>
  <joint
    name="Roller29"
    type="continuous">
    <origin
      xyz="0.0200893094200194 0.0208439097918678 -0.00799497322847992"
      rpy="0.915756260309541 3.61360050552819E-05 2.69284074366209" />
    <parent
      link="Omniwheel2" />
    <child
      link="Roller29" />
    <axis
      xyz="0.999999998240686 0 5.93180200794685E-05" />
  </joint>
  <link
    name="Roller210">
    <inertial>
      <origin
        xyz="0.00905625025870094 -6.24576147684186E-06 2.73642241810368E-07"
        rpy="0 0 0" />
      <mass
        value="0.00222805296382808" />
      <inertia
        ixx="6.29216525263325E-08"
        ixy="4.56563755034497E-13"
        ixz="3.52110698734384E-12"
        iyy="8.63039822829956E-08"
        iyz="6.6773618140882E-13"
        izz="8.63126436905977E-08" />
    </inertial>
    <visual>
      <origin
        xyz="0 0 0"
        rpy="0 0 0" />
      <geometry>
        <mesh
          filename="package://robotont_description/meshes/Roller210.STL" />
      </geometry>
      <material
        name="">
        <color
          rgba="0.792156862745098 0.819607843137255 0.933333333333333 1" />
      </material>
    </visual>
    <collision>
      <origin
        xyz="0 0 0"
        rpy="0 0 0" />
      <geometry>
        <mesh
          filename="package://robotont_description/meshes/Roller210.STL" />
      </geometry>
    </collision>
  </link>
  <joint
    name="Roller210"
    type="continuous">
    <origin
      xyz="0.0288219044427726 -0.00271048937951987 -0.00799497322847992"
      rpy="0.915756259459612 2.77555756156289E-17 1.7951958020513" />
    <parent
      link="Omniwheel2" />
    <child
      link="Roller210" />
    <axis
      xyz="1 0 0" />
  </joint>
  <link
    name="Roller211">
    <inertial>
      <origin
        xyz="0.00905625009736497 -6.24753680372736E-06 2.67396127878738E-07"
        rpy="0 0 0" />
      <mass
        value="0.00222805394526054" />
      <inertia
        ixx="6.29214201640515E-08"
        ixy="5.14120182555752E-13"
        ixz="3.51806755764717E-12"
        iyy="8.63039014768048E-08"
        iyz="6.92290007526507E-13"
        izz="8.63124959788257E-08" />
    </inertial>
    <visual>
      <origin
        xyz="0 0 0"
        rpy="0 0 0" />
      <geometry>
        <mesh
          filename="package://robotont_description/meshes/Roller211.STL" />
      </geometry>
      <material
        name="">
        <color
          rgba="0.792156862745098 0.819607843137255 0.933333333333333 1" />
      </material>
    </visual>
    <collision>
      <origin
        xyz="0 0 0"
        rpy="0 0 0" />
      <geometry>
        <mesh
          filename="package://robotont_description/meshes/Roller211.STL" />
      </geometry>
    </collision>
  </link>
  <joint
    name="Roller211"
    type="continuous">
    <origin
      xyz="0.0158510175604116 -0.0242238347642219 -0.00799497322847992"
      rpy="0.915756259459612 -3.46944695195361E-18 0.897597901025644" />
    <parent
      link="Omniwheel2" />
    <child
      link="Roller211" />
    <axis
      xyz="1 0 0" />
  </joint>
  <link
    name="Roller212">
    <inertial>
      <origin
        xyz="0.00905624833524948 -6.24471633453583E-06 2.57828610877864E-07"
        rpy="0 0 0" />
      <mass
        value="0.00222805665066196" />
      <inertia
        ixx="6.29210651014638E-08"
        ixy="4.52292954560405E-13"
        ixz="3.37176231636936E-12"
        iyy="8.63040908847963E-08"
        iyz="6.33004143857182E-13"
        izz="8.63121003647034E-08" />
    </inertial>
    <visual>
      <origin
        xyz="0 0 0"
        rpy="0 0 0" />
      <geometry>
        <mesh
          filename="package://robotont_description/meshes/Roller212.STL" />
      </geometry>
      <material
        name="">
        <color
          rgba="0.792156862745098 0.819607843137255 0.933333333333333 1" />
      </material>
    </visual>
    <collision>
      <origin
        xyz="0 0 0"
        rpy="0 0 0" />
      <geometry>
        <mesh
          filename="package://robotont_description/meshes/Roller212.STL" />
      </geometry>
    </collision>
  </link>
  <joint
    name="Roller212"
    type="continuous">
    <origin
      xyz="-0.00905600884677145 -0.0274961384952869 -0.00799497322847992"
      rpy="0.915756259459612 2.77555756156289E-17 1.11022302462516E-15" />
    <parent
      link="Omniwheel2" />
    <child
      link="Roller212" />
    <axis
      xyz="-1 0 0" />
  </joint>
  <link
    name="Roller213">
    <inertial>
      <origin
        xyz="0.00905625038827729 -6.24714957603301E-06 2.70082327336052E-07"
        rpy="0 0 0" />
      <mass
        value="0.00222805342991146" />
      <inertia
        ixx="6.29215392613625E-08"
        ixy="4.75412124638346E-13"
        ixz="3.51422277495841E-12"
        iyy="8.63039504534327E-08"
        iyz="6.52644833542814E-13"
        izz="8.63125575545934E-08" />
    </inertial>
    <visual>
      <origin
        xyz="0 0 0"
        rpy="0 0 0" />
      <geometry>
        <mesh
          filename="package://robotont_description/meshes/Roller213.STL" />
      </geometry>
      <material
        name="">
        <color
          rgba="0.792156862745098 0.819607843137255 0.933333333333333 1" />
      </material>
    </visual>
    <collision>
      <origin
        xyz="0 0 0"
        rpy="0 0 0" />
      <geometry>
        <mesh
          filename="package://robotont_description/meshes/Roller213.STL" />
      </geometry>
    </collision>
  </link>
  <joint
    name="Roller213"
    type="continuous">
    <origin
      xyz="-0.0271436758834209 -0.0100632891203917 -0.00799497322847992"
      rpy="0.915756259459612 8.32667268468867E-17 -0.897597901025656" />
    <parent
      link="Omniwheel2" />
    <child
      link="Roller213" />
    <axis
      xyz="-1 0 0" />
  </joint>
  <link
    name="Roller214">
    <inertial>
      <origin
        xyz="0.00905624844929193 -6.24340922089628E-06 1.13442568000499E-06"
        rpy="0 0 0" />
      <mass
        value="0.00222806047866909" />
      <inertia
        ixx="6.29206971756931E-08"
        ixy="5.35801228841074E-13"
        ixz="7.8851027640791E-13"
        iyy="8.63044839632031E-08"
        iyz="7.13398993197881E-13"
        izz="8.63114749631663E-08" />
    </inertial>
    <visual>
      <origin
        xyz="0 0 0"
        rpy="0 0 0" />
      <geometry>
        <mesh
          filename="package://robotont_description/meshes/Roller214.STL" />
      </geometry>
      <material
        name="">
        <color
          rgba="0.792156862745098 0.819607843137255 0.933333333333333 1" />
      </material>
    </visual>
    <collision>
      <origin
        xyz="0 0 0"
        rpy="0 0 0" />
      <geometry>
        <mesh
          filename="package://robotont_description/meshes/Roller214.STL" />
      </geometry>
    </collision>
  </link>
  <joint
    name="Roller214"
    type="continuous">
    <origin
      xyz="-0.0247916013497721 0.0149474222158466 -0.00799497322847992"
      rpy="0.915756261820527 6.02266757040028E-05 -1.79511740107518" />
    <parent
      link="Omniwheel2" />
    <child
      link="Roller214" />
    <axis
      xyz="-0.999999995113017 0 -9.88633677652673E-05" />
  </joint>
  <link
    name="Omniwheel3">
    <inertial>
      <origin
        xyz="5.79720891846769E-08 6.16550302173779E-07 -1.01595565876744E-07"
        rpy="0 0 0" />
      <mass
        value="0.0224355457660329" />
      <inertia
        ixx="5.90693960138509E-06"
        ixy="2.47088910184485E-10"
        ixz="4.46332660155843E-11"
        iyy="5.90479088638833E-06"
        iyz="1.78727612458747E-10"
        izz="1.03011808936408E-05" />
    </inertial>
    <visual>
      <origin
        xyz="0 0 0"
        rpy="0 0 0" />
      <geometry>
        <mesh
          filename="package://robotont_description/meshes/Omniwheel3.STL" />
      </geometry>
      <material
        name="">
        <color
          rgba="0.792156862745098 0.819607843137255 0.933333333333333 1" />
      </material>
    </visual>
    <collision>
      <origin
        xyz="0 0 0"
        rpy="0 0 0" />
      <geometry>
        <mesh
          filename="package://robotont_description/meshes/Omniwheel3.STL" />
      </geometry>
    </collision>
  </link>
  <joint
    name="Axle3"
    type="continuous">
    <origin
      xyz="0.248589957515507 -0.176606252233622 0.182850551353376"
      rpy="1.5707963267949 0.836473203822853 2.0943951023932" />
    <parent
      link="base_link" />
    <child
      link="Omniwheel3" />
    <axis
      xyz="0 0 1" />
  </joint>
  <link
    name="Roller31">
    <inertial>
      <origin
        xyz="0.00905624787173681 -6.24528032648619E-06 2.38164003768526E-07"
        rpy="0 0 0" />
      <mass
        value="0.00222806045765569" />
      <inertia
        ixx="6.29205719908983E-08"
        ixy="5.39748648536602E-13"
        ixz="3.16639247755353E-12"
        iyy="8.63043162349114E-08"
        iyz="6.86996034465331E-13"
        izz="8.63114980991218E-08" />
    </inertial>
    <visual>
      <origin
        xyz="0 0 0"
        rpy="0 0 0" />
      <geometry>
        <mesh
          filename="package://robotont_description/meshes/Roller31.STL" />
      </geometry>
      <material
        name="">
        <color
          rgba="0.792156862745098 0.819607843137255 0.933333333333333 1" />
      </material>
    </visual>
    <collision>
      <origin
        xyz="0 0 0"
        rpy="0 0 0" />
      <geometry>
        <mesh
          filename="package://robotont_description/meshes/Roller31.STL" />
      </geometry>
    </collision>
  </link>
  <joint
    name="Roller31"
    type="continuous">
    <origin
      xyz="-0.00905600884677155 0.0275059261982972 0.00800224940532271"
      rpy="0.362770953244144 -1.11022302462516E-16 1.33226762955019E-15" />
    <parent
      link="Omniwheel3" />
    <child
      link="Roller31" />
    <axis
      xyz="-1 0 0" />
  </joint>
  <link
    name="Roller32">
    <inertial>
      <origin
        xyz="0.0094066547458293 -0.00232009403807068 -0.0022684794293622"
        rpy="0 0 0" />
      <mass
        value="0.00222805197029901" />
      <inertia
        ixx="6.29218448969414E-08"
        ixy="5.45081794735808E-13"
        ixz="2.30876605256421E-12"
        iyy="8.63039777826319E-08"
        iyz="7.78390974672018E-13"
        izz="8.63127773426886E-08" />
    </inertial>
    <visual>
      <origin
        xyz="0 0 0"
        rpy="0 0 0" />
      <geometry>
        <mesh
          filename="package://robotont_description/meshes/Roller32.STL" />
      </geometry>
      <material
        name="">
        <color
          rgba="0.792156862745098 0.819607843137255 0.933333333333333 1" />
      </material>
    </visual>
    <collision>
      <origin
        xyz="0 0 0"
        rpy="0 0 0" />
      <geometry>
        <mesh
          filename="package://robotont_description/meshes/Roller32.STL" />
      </geometry>
    </collision>
  </link>
  <joint
    name="Roller32"
    type="continuous">
    <origin
      xyz="0.0167019792096861 0.0253504825559626 0.010944921054306"
      rpy="0.362770953711663 4.96327464154839E-05 -0.897579061938864" />
    <parent
      link="Omniwheel3" />
    <child
      link="Roller32" />
    <axis
      xyz="-0.99999999859084 0 -5.30878583584436E-05" />
  </joint>
  <link
    name="Roller33">
    <inertial>
      <origin
        xyz="0.00905624559101892 -6.24126316231544E-06 6.35088969275222E-07"
        rpy="0 0 0" />
      <mass
        value="0.00222806223295386" />
      <inertia
        ixx="6.29203200931261E-08"
        ixy="5.16361822938806E-13"
        ixz="2.05238924467419E-12"
        iyy="8.63044313430891E-08"
        iyz="7.26100080340593E-13"
        izz="8.63112609556247E-08" />
    </inertial>
    <visual>
      <origin
        xyz="0 0 0"
        rpy="0 0 0" />
      <geometry>
        <mesh
          filename="package://robotont_description/meshes/Roller33.STL" />
      </geometry>
      <material
        name="">
        <color
          rgba="0.792156862745098 0.819607843137255 0.933333333333333 1" />
      </material>
    </visual>
    <collision>
      <origin
        xyz="0 0 0"
        rpy="0 0 0" />
      <geometry>
        <mesh
          filename="package://robotont_description/meshes/Roller33.STL" />
      </geometry>
    </collision>
  </link>
  <joint
    name="Roller33"
    type="continuous">
    <origin
      xyz="0.0288314467476335 0.00270831141070442 0.00800224940532276"
      rpy="0.36277095356881 4.13606235316853E-05 -1.79518010281175" />
    <parent
      link="Omniwheel3" />
    <child
      link="Roller33" />
    <axis
      xyz="0.999999999021417 0 4.42398835973912E-05" />
  </joint>
  <link
    name="Roller34">
    <inertial>
      <origin
        xyz="0.00905625143376976 -6.24790759800112E-06 6.16364556782489E-07"
        rpy="0 0 0" />
      <mass
        value="0.00222804787412911" />
      <inertia
        ixx="6.29223289044615E-08"
        ixy="4.50055316451044E-13"
        ixz="2.94031984429377E-12"
        iyy="8.63037054622645E-08"
        iyz="6.84950730663491E-13"
        izz="8.63133856974042E-08" />
    </inertial>
    <visual>
      <origin
        xyz="0 0 0"
        rpy="0 0 0" />
      <geometry>
        <mesh
          filename="package://robotont_description/meshes/Roller34.STL" />
      </geometry>
      <material
        name="">
        <color
          rgba="0.792156862745098 0.819607843137255 0.933333333333333 1" />
      </material>
    </visual>
    <collision>
      <origin
        xyz="0 0 0"
        rpy="0 0 0" />
      <geometry>
        <mesh
          filename="package://robotont_description/meshes/Roller34.STL" />
      </geometry>
    </collision>
  </link>
  <joint
    name="Roller34"
    type="continuous">
    <origin
      xyz="0.0200935561451987 -0.0208527282075686 0.00800224940532279"
      rpy="0.362770953451931 3.30884973658167E-05 -2.69278114368587" />
    <parent
      link="Omniwheel3" />
    <child
      link="Roller34" />
    <axis
      xyz="0.999999999373707 0 3.53919053182605E-05" />
  </joint>
  <link
    name="Roller35">
    <inertial>
      <origin
        xyz="0.00905624995479037 -6.24557252443259E-06 4.86696796836439E-07"
        rpy="0 0 0" />
      <mass
        value="0.00222805834897051" />
      <inertia
        ixx="6.29209806512652E-08"
        ixy="6.2008663988909E-13"
        ixz="2.60654690748146E-12"
        iyy="8.63043130196061E-08"
        iyz="7.99337421387891E-13"
        izz="8.63118109519943E-08" />
    </inertial>
    <visual>
      <origin
        xyz="0 0 0"
        rpy="0 0 0" />
      <geometry>
        <mesh
          filename="package://robotont_description/meshes/Roller35.STL" />
      </geometry>
      <material
        name="">
        <color
          rgba="0.792156862745098 0.819607843137255 0.933333333333333 1" />
      </material>
    </visual>
    <collision>
      <origin
        xyz="0 0 0"
        rpy="0 0 0" />
      <geometry>
        <mesh
          filename="package://robotont_description/meshes/Roller35.STL" />
      </geometry>
    </collision>
  </link>
  <joint
    name="Roller35"
    type="continuous">
    <origin
      xyz="-0.00377519206841903 -0.0287112381674062 0.00800224940532276"
      rpy="0.362770953361025 2.48163744038319E-05 2.6928031226208" />
    <parent
      link="Omniwheel3" />
    <child
      link="Roller35" />
    <axis
      xyz="0.99999999964771 0 2.65439304664439E-05" />
  </joint>
  <link
    name="Roller36">
    <inertial>
      <origin
        xyz="0.00905625104762144 -6.24611077354453E-06 4.62913676307908E-07"
        rpy="0 0 0" />
      <mass
        value="0.00222804656940515" />
      <inertia
        ixx="6.29225306252793E-08"
        ixy="4.72283946465801E-13"
        ixz="3.40170159428551E-12"
        iyy="8.6303644029232E-08"
        iyz="7.44540082317808E-13"
        izz="8.63136150869427E-08" />
    </inertial>
    <visual>
      <origin
        xyz="0 0 0"
        rpy="0 0 0" />
      <geometry>
        <mesh
          filename="package://robotont_description/meshes/Roller36.STL" />
      </geometry>
      <material
        name="">
        <color
          rgba="0.792156862745098 0.819607843137255 0.933333333333333 1" />
      </material>
    </visual>
    <collision>
      <origin
        xyz="0 0 0"
        rpy="0 0 0" />
      <geometry>
        <mesh
          filename="package://robotont_description/meshes/Roller36.STL" />
      </geometry>
    </collision>
  </link>
  <joint
    name="Roller36"
    type="continuous">
    <origin
      xyz="-0.0248011436546332 -0.0149496001846614 0.00800224940532274"
      rpy="0.362770953296091 1.65442494612698E-05 1.79520208174714" />
    <parent
      link="Omniwheel3" />
    <child
      link="Roller36" />
    <axis
      xyz="0.999999999843427 0 1.76959534889387E-05" />
  </joint>
  <link
    name="Roller37">
    <inertial>
      <origin
        xyz="0.00905624895709439 -6.24613275246322E-06 3.55229698906223E-07"
        rpy="0 0 0" />
      <mass
        value="0.00222805304022832" />
      <inertia
        ixx="6.29215166700992E-08"
        ixy="4.43264304285288E-13"
        ixz="3.38032033265257E-12"
        iyy="8.63038097226509E-08"
        iyz="6.68643801374989E-13"
        izz="8.63126909132346E-08" />
    </inertial>
    <visual>
      <origin
        xyz="0 0 0"
        rpy="0 0 0" />
      <geometry>
        <mesh
          filename="package://robotont_description/meshes/Roller37.STL" />
      </geometry>
      <material
        name="">
        <color
          rgba="0.792156862745098 0.819607843137255 0.933333333333333 1" />
      </material>
    </visual>
    <collision>
      <origin
        xyz="0 0 0"
        rpy="0 0 0" />
      <geometry>
        <mesh
          filename="package://robotont_description/meshes/Roller37.STL" />
      </geometry>
    </collision>
  </link>
  <joint
    name="Roller37"
    type="continuous">
    <origin
      xyz="-0.0271513282177754 0.0100693916534027 0.00800224940532274"
      rpy="0.362770953257131 8.27212416263931E-06 0.897601040873349" />
    <parent
      link="Omniwheel3" />
    <child
      link="Roller37" />
    <axis
      xyz="-0.999999999960857 0 0" />
  </joint>
  <link
    name="Roller38">
    <inertial>
      <origin
        xyz="0.00905624789574405 -6.24573164095116E-06 9.68911569504405E-07"
        rpy="0 0 0" />
      <mass
        value="0.00222805753419375" />
      <inertia
        ixx="6.29208587950535E-08"
        ixy="5.03805611046633E-13"
        ixz="1.51564747193346E-12"
        iyy="8.63040348496228E-08"
        iyz="6.63564101180102E-13"
        izz="8.6311963548113E-08" />
    </inertial>
    <visual>
      <origin
        xyz="0 0 0"
        rpy="0 0 0" />
      <geometry>
        <mesh
          filename="package://robotont_description/meshes/Roller38.STL" />
      </geometry>
      <material
        name="">
        <color
          rgba="0.792156862745098 0.819607843137255 0.933333333333333 1" />
      </material>
    </visual>
    <collision>
      <origin
        xyz="0 0 0"
        rpy="0 0 0" />
      <geometry>
        <mesh
          filename="package://robotont_description/meshes/Roller38.STL" />
      </geometry>
    </collision>
  </link>
  <joint
    name="Roller38"
    type="continuous">
    <origin
      xyz="-0.00377094534323918 0.0287024197517056 -0.00799497322847989"
      rpy="0.915756260970598 4.81813406629683E-05 -2.69273098229598" />
    <parent
      link="Omniwheel3" />
    <child
      link="Roller38" />
    <axis
      xyz="0.999999996872331 0 7.90906943933245E-05" />
  </joint>
  <link
    name="Roller39">
    <inertial>
      <origin
        xyz="0.00905625044881725 -6.24554927827758E-06 7.84030141962044E-07"
        rpy="0 0 0" />
      <mass
        value="0.00222805824992304" />
      <inertia
        ixx="6.29210276532831E-08"
        ixy="5.77427693313535E-13"
        ixz="1.82368679600854E-12"
        iyy="8.63043752824001E-08"
        iyz="7.54821829622173E-13"
        izz="8.63117923430472E-08" />
    </inertial>
    <visual>
      <origin
        xyz="0 0 0"
        rpy="0 0 0" />
      <geometry>
        <mesh
          filename="package://robotont_description/meshes/Roller39.STL" />
      </geometry>
      <material
        name="">
        <color
          rgba="0.792156862745098 0.819607843137255 0.933333333333333 1" />
      </material>
    </visual>
    <collision>
      <origin
        xyz="0 0 0"
        rpy="0 0 0" />
      <geometry>
        <mesh
          filename="package://robotont_description/meshes/Roller39.STL" />
      </geometry>
    </collision>
  </link>
  <joint
    name="Roller39"
    type="continuous">
    <origin
      xyz="0.0200893094200194 0.0208439097918677 -0.00799497322847993"
      rpy="0.915756260309542 3.61360050556799E-05 2.69284074366209" />
    <parent
      link="Omniwheel3" />
    <child
      link="Roller39" />
    <axis
      xyz="0.999999998240686 0 5.9318020079635E-05" />
  </joint>
  <link
    name="Roller310">
    <inertial>
      <origin
        xyz="0.00905625222249336 -6.2473636815441E-06 6.71365827570325E-07"
        rpy="0 0 0" />
      <mass
        value="0.00222804374997192" />
      <inertia
        ixx="6.29230745061036E-08"
        ixy="4.46612720152558E-13"
        ixz="2.96158483216721E-12"
        iyy="8.63036712718867E-08"
        iyz="7.33918204205309E-13"
        izz="8.63140165126992E-08" />
    </inertial>
    <visual>
      <origin
        xyz="0 0 0"
        rpy="0 0 0" />
      <geometry>
        <mesh
          filename="package://robotont_description/meshes/Roller310.STL" />
      </geometry>
      <material
        name="">
        <color
          rgba="0.792156862745098 0.819607843137255 0.933333333333333 1" />
      </material>
    </visual>
    <collision>
      <origin
        xyz="0 0 0"
        rpy="0 0 0" />
      <geometry>
        <mesh
          filename="package://robotont_description/meshes/Roller310.STL" />
      </geometry>
    </collision>
  </link>
  <joint
    name="Roller310"
    type="continuous">
    <origin
      xyz="0.0288219044427725 -0.0027104893795199 -0.00799497322847992"
      rpy="0.915756259837358 2.40906703979625E-05 1.79522716244185" />
    <parent
      link="Omniwheel3" />
    <child
      link="Roller310" />
    <axis
      xyz="0.999999999218083 0 3.95453473166496E-05" />
  </joint>
  <link
    name="Roller311">
    <inertial>
      <origin
        xyz="0.00905624835970248 -6.24465132428864E-06 4.57902463807391E-07"
        rpy="0 0 0" />
      <mass
        value="0.00222805243059925" />
      <inertia
        ixx="6.29215170641379E-08"
        ixy="5.20223051732387E-13"
        ixz="3.1877850345495E-12"
        iyy="8.63036766070656E-08"
        iyz="7.83995881071619E-13"
        izz="8.63128053203237E-08" />
    </inertial>
    <visual>
      <origin
        xyz="0 0 0"
        rpy="0 0 0" />
      <geometry>
        <mesh
          filename="package://robotont_description/meshes/Roller311.STL" />
      </geometry>
      <material
        name="">
        <color
          rgba="0.792156862745098 0.819607843137255 0.933333333333333 1" />
      </material>
    </visual>
    <collision>
      <origin
        xyz="0 0 0"
        rpy="0 0 0" />
      <geometry>
        <mesh
          filename="package://robotont_description/meshes/Roller311.STL" />
      </geometry>
    </collision>
  </link>
  <joint
    name="Roller311"
    type="continuous">
    <origin
      xyz="0.0158510175604116 -0.0242238347642219 -0.00799497322847988"
      rpy="0.915756259554048 1.20453338996044E-05 0.897613581219221" />
    <parent
      link="Omniwheel3" />
    <child
      link="Roller311" />
    <axis
      xyz="-0.999999999804521 0 -1.97726715267521E-05" />
  </joint>
  <link
    name="Roller312">
    <inertial>
      <origin
        xyz="0.0090562489265269 -6.24347960770377E-06 2.46051895802513E-07"
        rpy="0 0 0" />
      <mass
        value="0.00222805909473683" />
      <inertia
        ixx="6.29208677635619E-08"
        ixy="4.81038307883422E-13"
        ixz="3.18158805715812E-12"
        iyy="8.63044087601722E-08"
        iyz="6.69684137937493E-13"
        izz="8.6311673152322E-08" />
    </inertial>
    <visual>
      <origin
        xyz="0 0 0"
        rpy="0 0 0" />
      <geometry>
        <mesh
          filename="package://robotont_description/meshes/Roller312.STL" />
      </geometry>
      <material
        name="">
        <color
          rgba="0.792156862745098 0.819607843137255 0.933333333333333 1" />
      </material>
    </visual>
    <collision>
      <origin
        xyz="0 0 0"
        rpy="0 0 0" />
      <geometry>
        <mesh
          filename="package://robotont_description/meshes/Roller312.STL" />
      </geometry>
    </collision>
  </link>
  <joint
    name="Roller312"
    type="continuous">
    <origin
      xyz="-0.00905600884677144 -0.0274961384952869 -0.00799497322847989"
      rpy="0.915756259459611 -1.11022302462516E-16 1.27675647831893E-15" />
    <parent
      link="Omniwheel3" />
    <child
      link="Roller312" />
    <axis
      xyz="-1 0 0" />
  </joint>
  <link
    name="Roller313">
    <inertial>
      <origin
        xyz="0.00905625118942394 -6.2473828312537E-06 2.70984599981539E-07"
        rpy="0 0 0" />
      <mass
        value="0.00222805294277978" />
      <inertia
        ixx="6.29216704053611E-08"
        ixy="4.88768896677513E-13"
        ixz="3.50326432455678E-12"
        iyy="8.63040004929791E-08"
        iyz="6.57184999729148E-13"
        izz="8.6312611211984E-08" />
    </inertial>
    <visual>
      <origin
        xyz="0 0 0"
        rpy="0 0 0" />
      <geometry>
        <mesh
          filename="package://robotont_description/meshes/Roller313.STL" />
      </geometry>
      <material
        name="">
        <color
          rgba="0.792156862745098 0.819607843137255 0.933333333333333 1" />
      </material>
    </visual>
    <collision>
      <origin
        xyz="0 0 0"
        rpy="0 0 0" />
      <geometry>
        <mesh
          filename="package://robotont_description/meshes/Roller313.STL" />
      </geometry>
    </collision>
  </link>
  <joint
    name="Roller313"
    type="continuous">
    <origin
      xyz="-0.027143675883421 -0.0100632891203918 -0.00799497322847988"
      rpy="0.915756259459612 -5.96744875736022E-16 -0.897597901025656" />
    <parent
      link="Omniwheel3" />
    <child
      link="Roller313" />
    <axis
      xyz="-1 0 0" />
  </joint>
  <link
    name="Roller314">
    <inertial>
      <origin
        xyz="0.00905624765596219 -6.24247202157813E-06 1.14411365514933E-06"
        rpy="0 0 0" />
      <mass
        value="0.00222805889351307" />
      <inertia
        ixx="6.29208101465886E-08"
        ixy="4.93817546282784E-13"
        ixz="9.28428188516905E-13"
        iyy="8.63042910771102E-08"
        iyz="7.09403601173196E-13"
        izz="8.63117476348948E-08" />
    </inertial>
    <visual>
      <origin
        xyz="0 0 0"
        rpy="0 0 0" />
      <geometry>
        <mesh
          filename="package://robotont_description/meshes/Roller314.STL" />
      </geometry>
      <material
        name="">
        <color
          rgba="0.792156862745098 0.819607843137255 0.933333333333333 1" />
      </material>
    </visual>
    <collision>
      <origin
        xyz="0 0 0"
        rpy="0 0 0" />
      <geometry>
        <mesh
          filename="package://robotont_description/meshes/Roller314.STL" />
      </geometry>
    </collision>
  </link>
  <joint
    name="Roller314"
    type="continuous">
    <origin
      xyz="-0.0247916013497721 0.0149474222158465 -0.00799497322847988"
      rpy="0.915756261820527 6.02266757033729E-05 -1.79511740107518" />
    <parent
      link="Omniwheel3" />
    <child
      link="Roller314" />
    <axis
      xyz="0.999999995113017 0 9.88633677658605E-05" />
  </joint>
</robot>
