<robot
  name="robotont_description">
  <link
    name="base_link">
    <inertial>
      <origin
        xyz="0.13545 0.19184 0.25433"
        rpy="0 0 0" />
      <mass
        value="0.8967" />
      <inertia
        ixx="0.0047703"
        ixy="9.9652E-07"
        ixz="1.0978E-06"
        iyy="0.0093778"
        iyz="-3.8742E-06"
        izz="0.0058755" />
    </inertial>
    <visual>
      <origin
        xyz="0 0 0"
        rpy="0 0 0" />
      <geometry>
        <mesh
          filename="package://robotont_description/meshes/base_link.stl" />
      </geometry>
      <material
        name="">
        <color
          rgba="1 1 1 1" />
      </material>
    </visual>
    <collision>
      <origin
        xyz="0 0 0"
        rpy="0 0 0" />
      <geometry>
        <mesh
          filename="package://robotont_description/meshes/base_link.stl" />
      </geometry>
    </collision>
  </link>
  <link
    name="Omniwheel1">
    <inertial>
      <origin
        xyz="5.5112E-08 6.1765E-07 -9.6607E-08"
        rpy="0 0 0" />
      <mass
        value="0.022436" />
      <inertia
        ixx="5.9069E-06"
        ixy="2.4748E-10"
        ixz="4.4625E-11"
        iyy="5.9048E-06"
        iyz="1.7693E-10"
        izz="1.0301E-05" />
    </inertial>
    <visual>
      <origin
        xyz="0 0 0"
        rpy="0 0 0" />
      <geometry>
        <mesh
          filename="package://robotont_description/meshes/Omniwheel1.stl" />
      </geometry>
      <material
        name="">
        <color
          rgba="0.79216 0.81961 0.93333 1" />
      </material>
    </visual>
    <collision>
      <origin
        xyz="0 0 0"
        rpy="0 0 0" />
      <geometry>
        <mesh
          filename="package://robotont_description/meshes/Omniwheel1.stl" />
      </geometry>
    </collision>
  </link>
  <joint
    name="Axle1"
    type="continuous">
    <origin
      xyz="0.022326481506329 -0.176779457314387 0.182850551353376"
      rpy="1.5707963267949 0.836473203822852 -2.09439510239319" />
    <parent
      link="base_link" />
    <child
      link="Omniwheel1" />
    <axis
      xyz="0 0 -1" />
  </joint>
  <link
    name="Roller11">
    <inertial>
      <origin
        xyz="2.38846604785903E-07 0.0275000951528096 2.4370655343775E-07"
        rpy="0 0 0" />
      <mass
        value="0.00222805970857661" />
      <inertia
        ixx="6.29206948993393E-08"
        ixy="4.88962427767844E-13"
        ixz="3.19630145456217E-12"
        iyy="8.63043199686778E-08"
        iyz="6.68903337023421E-13"
        izz="8.63116179634987E-08" />
    </inertial>
    <visual>
      <origin
        xyz="0 0 0"
        rpy="0 0 0" />
      <geometry>
        <mesh
          filename="package://robotont_description/meshes/Roller11.stl" />
      </geometry>
      <material
        name="">
        <color
          rgba="0.792156862745098 0.819607843137255 0.933333333333333 1" />
      </material>
    </visual>
    <collision>
      <origin
        xyz="0 0 0"
        rpy="0 0 0" />
      <geometry>
        <mesh
          filename="package://robotont_description/meshes/Roller11.stl" />
      </geometry>
    </collision>
  </link>
  <joint
    name="Roller11"
    type="continuous">
    <origin
      xyz="0 0.0017898 -0.0017588"
      rpy="0.36277 4.996E-16 -2.2204E-16" />
    <parent
      link="Omniwheel1" />
    <child
      link="Roller11" />
    <axis
      xyz="-1 0 0" />
  </joint>
  <link
    name="Roller12">
    <inertial>
      <origin
        xyz="0.00139954744127704 0.0281301052391737 -0.000238861386644029"
        rpy="0 0 0" />
      <mass
        value="0.00222805300985277" />
      <inertia
        ixx="6.29215435642388E-08"
        ixy="5.17346915351986E-13"
        ixz="3.55409401429373E-12"
        iyy="8.6303869517361E-08"
        iyz="7.08824009685855E-13"
        izz="8.63126286853934E-08" />
    </inertial>
    <visual>
      <origin
        xyz="0 0 0"
        rpy="0 0 0" />
      <geometry>
        <mesh
          filename="package://robotont_description/meshes/Roller12.stl" />
      </geometry>
      <material
        name="">
        <color
          rgba="0.792156862745098 0.819607843137255 0.933333333333333 1" />
      </material>
    </visual>
    <collision>
      <origin
        xyz="0 0 0"
        rpy="0 0 0" />
      <geometry>
        <mesh
          filename="package://robotont_description/meshes/Roller12.stl" />
      </geometry>
    </collision>
  </link>
  <joint
    name="Roller12"
    type="continuous">
    <origin
      xyz="0 0.00178977984606152 -0.00175882060681612"
      rpy="0.362770953244145 1.33226762955019E-15 -0.897597901025656" />
    <parent
      link="Omniwheel1" />
    <child
      link="Roller12" />
    <axis
      xyz="-1 0 0" />
  </joint>
  <link
    name="Roller13">
    <inertial>
      <origin
        xyz="0.0013995464014836 0.0281301079406411 -0.000238883722221875"
        rpy="0 0 0" />
      <mass
        value="0.00222805817486766" />
      <inertia
        ixx="6.29209569451157E-08"
        ixy="4.92470110990585E-13"
        ixz="3.24237434941171E-12"
        iyy="8.63043189882584E-08"
        iyz="6.78746862996581E-13"
        izz="8.63118153274778E-08" />
    </inertial>
    <visual>
      <origin
        xyz="0 0 0"
        rpy="0 0 0" />
      <geometry>
        <mesh
          filename="package://robotont_description/meshes/Roller13.stl" />
      </geometry>
      <material
        name="">
        <color
          rgba="0.792156862745098 0.819607843137255 0.933333333333333 1" />
      </material>
    </visual>
    <collision>
      <origin
        xyz="0 0 0"
        rpy="0 0 0" />
      <geometry>
        <mesh
          filename="package://robotont_description/meshes/Roller13.stl" />
      </geometry>
    </collision>
  </link>
  <joint
    name="Roller13"
    type="continuous">
    <origin
      xyz="0.0013993062303377 0.00111590948159165 -0.00175882060681612"
      rpy="0.362770953244145 8.88178419700125E-16 -1.79519580205131" />
    <parent
      link="Omniwheel1" />
    <child
      link="Roller13" />
    <axis
      xyz="-1 0 0" />
  </joint>
  <link
    name="Roller14">
    <inertial>
      <origin
        xyz="2.40999099926364E-07 0.0285492425757234 -0.00227918690746462"
        rpy="0 0 0" />
      <mass
        value="0.00222804814526446" />
      <inertia
        ixx="6.29221517052428E-08"
        ixy="5.00910377681433E-13"
        ixz="3.81053818495371E-12"
        iyy="8.63035277887356E-08"
        iyz="7.65727413962495E-13"
        izz="8.63134098323392E-08" />
    </inertial>
    <visual>
      <origin
        xyz="0 0 0"
        rpy="0 0 0" />
      <geometry>
        <mesh
          filename="package://robotont_description/meshes/Roller14.stl" />
      </geometry>
      <material
        name="">
        <color
          rgba="0.792156862745098 0.819607843137255 0.933333333333333 1" />
      </material>
    </visual>
    <collision>
      <origin
        xyz="0 0 0"
        rpy="0 0 0" />
      <geometry>
        <mesh
          filename="package://robotont_description/meshes/Roller14.stl" />
      </geometry>
    </collision>
  </link>
  <joint
    name="Roller14"
    type="continuous">
    <origin
      xyz="0 0 0"
      rpy="0.362770953244144 -1.66533453693773E-16 -2.69279370307697" />
    <parent
      link="Omniwheel1" />
    <child
      link="Roller14" />
    <axis
      xyz="1 0 0" />
  </joint>
  <link
    name="Roller15">
    <inertial>
      <origin
        xyz="0.00139954727307445 0.0281301065325559 -0.000238887080345349"
        rpy="0 0 0" />
      <mass
        value="0.00222805836001247" />
      <inertia
        ixx="6.29209663359342E-08"
        ixy="6.21969489422179E-13"
        ixz="3.23127866334573E-12"
        iyy="8.63043154156049E-08"
        iyz="8.09870792372604E-13"
        izz="8.6311798452068E-08" />
    </inertial>
    <visual>
      <origin
        xyz="0 0 0"
        rpy="0 0 0" />
      <geometry>
        <mesh
          filename="package://robotont_description/meshes/Roller15.stl" />
      </geometry>
      <material
        name="">
        <color
          rgba="0.792156862745098 0.819607843137255 0.933333333333333 1" />
      </material>
    </visual>
    <collision>
      <origin
        xyz="0 0 0"
        rpy="0 0 0" />
      <geometry>
        <mesh
          filename="package://robotont_description/meshes/Roller15.stl" />
      </geometry>
    </collision>
  </link>
  <joint
    name="Roller15"
    type="continuous">
    <origin
      xyz="0.000776556371806431 -0.00161253592170063 -0.00175882060681613"
      rpy="0.362770953244145 2.35922392732846E-16 2.69279370307696" />
    <parent
      link="Omniwheel1" />
    <child
      link="Roller15" />
    <axis
      xyz="1 0 0" />
  </joint>
  <link
    name="Roller16">
    <inertial>
      <origin
        xyz="0.0013995491032327 0.0281301061696096 -0.000238827021645793"
        rpy="0 0 0" />
      <mass
        value="0.00222804542902184" />
      <inertia
        ixx="6.29227703784478E-08"
        ixy="4.97231122536218E-13"
        ixz="3.83859404315335E-12"
        iyy="8.63036751661586E-08"
        iyz="7.99137761359059E-13"
        izz="8.63137762960445E-08" />
    </inertial>
    <visual>
      <origin
        xyz="0 0 0"
        rpy="0 0 0" />
      <geometry>
        <mesh
          filename="package://robotont_description/meshes/Roller16.stl" />
      </geometry>
      <material
        name="">
        <color
          rgba="0.792156862745098 0.819607843137255 0.933333333333333 1" />
      </material>
    </visual>
    <collision>
      <origin
        xyz="0 0 0"
        rpy="0 0 0" />
      <geometry>
        <mesh
          filename="package://robotont_description/meshes/Roller16.stl" />
      </geometry>
    </collision>
  </link>
  <joint
    name="Roller16"
    type="continuous">
    <origin
      xyz="-0.000776556371806417 -0.0016125359217006 -0.00175882060681613"
      rpy="0.362770953244145 -5.82867087928207E-16 1.7951958020513" />
    <parent
      link="Omniwheel1" />
    <child
      link="Roller16" />
    <axis
      xyz="1 0 0" />
  </joint>
  <link
    name="Roller17">
    <inertial>
      <origin
        xyz="-0.00139906793201658 0.0281301075525815 -0.000238882107263749"
        rpy="0 0 0" />
      <mass
        value="0.00222805825576709" />
      <inertia
        ixx="6.2920792801336E-08"
        ixy="5.05426131790101E-13"
        ixz="3.34562067322485E-12"
        iyy="8.63040811412926E-08"
        iyz="7.29474021611283E-13"
        izz="8.6311903812652E-08" />
    </inertial>
    <visual>
      <origin
        xyz="0 0 0"
        rpy="0 0 0" />
      <geometry>
        <mesh
          filename="package://robotont_description/meshes/Roller17.stl" />
      </geometry>
      <material
        name="">
        <color
          rgba="0.792156862745098 0.819607843137255 0.933333333333333 1" />
      </material>
    </visual>
    <collision>
      <origin
        xyz="0 0 0"
        rpy="0 0 0" />
      <geometry>
        <mesh
          filename="package://robotont_description/meshes/Roller17.stl" />
      </geometry>
    </collision>
  </link>
  <joint
    name="Roller17"
    type="continuous">
    <origin
      xyz="0 0.00178977984606152 -0.00175882060681612"
      rpy="0.362770953244145 -1.11022302462516E-15 0.897597901025643" />
    <parent
      link="Omniwheel1" />
    <child
      link="Roller17" />
    <axis
      xyz="1 0 0" />
  </joint>
  <link
    name="Roller18">
    <inertial>
      <origin
        xyz="2.42663856994674E-07 0.0275000911230207 3.00102067807284E-07"
        rpy="0 0 0" />
      <mass
        value="0.00222804667573871" />
      <inertia
        ixx="6.29224693136473E-08"
        ixy="5.17072599094016E-13"
        ixz="3.82594955712515E-12"
        iyy="8.63035856870093E-08"
        iyz="7.59590640726388E-13"
        izz="8.63135840288425E-08" />
    </inertial>
    <visual>
      <origin
        xyz="0 0 0"
        rpy="0 0 0" />
      <geometry>
        <mesh
          filename="package://robotont_description/meshes/Roller18.stl" />
      </geometry>
      <material
        name="">
        <color
          rgba="0.792156862745098 0.819607843137255 0.933333333333333 1" />
      </material>
    </visual>
    <collision>
      <origin
        xyz="0 0 0"
        rpy="0 0 0" />
      <geometry>
        <mesh
          filename="package://robotont_description/meshes/Roller18.stl" />
      </geometry>
    </collision>
  </link>
  <joint
    name="Roller18"
    type="continuous">
    <origin
      xyz="-0.019201 0.03987 -0.029808"
      rpy="0.91576 -4.4409E-16 -2.6928" />
    <parent
      link="Omniwheel1" />
    <child
      link="Roller18" />
    <axis
      xyz="1 0 0" />
  </joint>
  <link
    name="Roller19">
    <inertial>
      <origin
        xyz="2.42185021870345E-07 0.027500092705667 2.47279483861496E-07"
        rpy="0 0 0" />
      <mass
        value="0.00222805805773092" />
      <inertia
        ixx="6.29210771801885E-08"
        ixy="5.50593872529898E-13"
        ixz="3.2074200276689E-12"
        iyy="8.63044063542196E-08"
        iyz="7.2180173969331E-13"
        izz="8.63117961136409E-08" />
    </inertial>
    <visual>
      <origin
        xyz="0 0 0"
        rpy="0 0 0" />
      <geometry>
        <mesh
          filename="package://robotont_description/meshes/Roller19.stl" />
      </geometry>
      <material
        name="">
        <color
          rgba="0.792156862745098 0.819607843137255 0.933333333333333 1" />
      </material>
    </visual>
    <collision>
      <origin
        xyz="0 0 0"
        rpy="0 0 0" />
      <geometry>
        <mesh
          filename="package://robotont_description/meshes/Roller19.stl" />
      </geometry>
    </collision>
  </link>
  <joint
    name="Roller19"
    type="continuous">
    <origin
      xyz="0.0192005499375979 0.0398703527713769 -0.0298081468021298"
      rpy="0.915756259459612 -4.71844785465692E-16 2.69279370307696" />
    <parent
      link="Omniwheel1" />
    <child
      link="Roller19" />
    <axis
      xyz="1 0 0" />
  </joint>
  <link
    name="Roller110">
    <inertial>
      <origin
        xyz="2.44333479948455E-07 0.0275000917272284 2.95757060703172E-07"
        rpy="0 0 0" />
      <mass
        value="0.00222804736414082" />
      <inertia
        ixx="6.29226598347543E-08"
        ixy="4.52977356185977E-13"
        ixz="3.69077319777347E-12"
        iyy="8.6303969161013E-08"
        iyz="7.09495764163114E-13"
        izz="8.63134355109721E-08" />
    </inertial>
    <visual>
      <origin
        xyz="0 0 0"
        rpy="0 0 0" />
      <geometry>
        <mesh
          filename="package://robotont_description/meshes/Roller110.stl" />
      </geometry>
      <material
        name="">
        <color
          rgba="0.792156862745098 0.819607843137255 0.933333333333333 1" />
      </material>
    </visual>
    <collision>
      <origin
        xyz="0 0 0"
        rpy="0 0 0" />
      <geometry>
        <mesh
          filename="package://robotont_description/meshes/Roller110.stl" />
      </geometry>
    </collision>
  </link>
  <joint
    name="Roller110"
    type="continuous">
    <origin
      xyz="0.0431432440899406 0.00984716392754997 -0.0298081468021298"
      rpy="0.915756259459611 -2.22044604925031E-16 1.7951958020513" />
    <parent
      link="Omniwheel1" />
    <child
      link="Roller110" />
    <axis
      xyz="1 0 0" />
  </joint>
  <link
    name="Roller111">
    <inertial>
      <origin
        xyz="2.37411410863864E-07 0.0275000955321716 2.4271493909156E-07"
        rpy="0 0 0" />
      <mass
        value="0.00222806016762835" />
      <inertia
        ixx="6.29205129246595E-08"
        ixy="5.80162961639431E-13"
        ixz="3.24970972219565E-12"
        iyy="8.63041758522932E-08"
        iyz="7.96497449659853E-13"
        izz="8.63116043441868E-08" />
    </inertial>
    <visual>
      <origin
        xyz="0 0 0"
        rpy="0 0 0" />
      <geometry>
        <mesh
          filename="package://robotont_description/meshes/Roller111.stl" />
      </geometry>
      <material
        name="">
        <color
          rgba="0.792156862745098 0.819607843137255 0.933333333333333 1" />
      </material>
    </visual>
    <collision>
      <origin
        xyz="0 0 0"
        rpy="0 0 0" />
      <geometry>
        <mesh
          filename="package://robotont_description/meshes/Roller111.stl" />
      </geometry>
    </collision>
  </link>
  <joint
    name="Roller111"
    type="continuous">
    <origin
      xyz="0.0345981954807621 -0.0275911401992598 -0.0298081468021298"
      rpy="0.915756259459612 -3.33066907387547E-16 0.897597901025643" />
    <parent
      link="Omniwheel1" />
    <child
      link="Roller111" />
    <axis
      xyz="1 0 0" />
  </joint>
  <link
    name="Roller112">
    <inertial>
      <origin
        xyz="2.3734264539832E-07 0.0275000947936796 2.1996671284441E-07"
        rpy="0 0 0" />
      <mass
        value="0.00222806454853658" />
      <inertia
        ixx="6.29200674487059E-08"
        ixy="5.35910979404938E-13"
        ixz="2.91645592249648E-12"
        iyy="8.63046137513934E-08"
        iyz="6.66749567405019E-13"
        izz="8.63108639696968E-08" />
    </inertial>
    <visual>
      <origin
        xyz="0 0 0"
        rpy="0 0 0" />
      <geometry>
        <mesh
          filename="package://robotont_description/meshes/Roller112.stl" />
      </geometry>
      <material
        name="">
        <color
          rgba="0.792156862745098 0.819607843137255 0.933333333333333 1" />
      </material>
    </visual>
    <collision>
      <origin
        xyz="0 0 0"
        rpy="0 0 0" />
      <geometry>
        <mesh
          filename="package://robotont_description/meshes/Roller112.stl" />
      </geometry>
    </collision>
  </link>
  <joint
    name="Roller112"
    type="continuous">
    <origin
      xyz="0 -0.0442527529993359 -0.0298081468021298"
      rpy="0.915756259459611 1.11022302462516E-16 9.43689570931383E-16" />
    <parent
      link="Omniwheel1" />
    <child
      link="Roller112" />
    <axis
      xyz="-1 0 0" />
  </joint>
  <link
    name="Roller113">
    <inertial>
      <origin
        xyz="2.43107489250605E-07 0.0275000921244067 2.74506474134961E-07"
        rpy="0 0 0" />
      <mass
        value="0.00222805215455413" />
      <inertia
        ixx="6.29218607574591E-08"
        ixy="5.18625747573981E-13"
        ixz="3.52160152930651E-12"
        iyy="8.6304043308765E-08"
        iyz="7.34598956846743E-13"
        izz="8.63127290887446E-08" />
    </inertial>
    <visual>
      <origin
        xyz="0 0 0"
        rpy="0 0 0" />
      <geometry>
        <mesh
          filename="package://robotont_description/meshes/Roller113.stl" />
      </geometry>
      <material
        name="">
        <color
          rgba="0.792156862745098 0.819607843137255 0.933333333333333 1" />
      </material>
    </visual>
    <collision>
      <origin
        xyz="0 0 0"
        rpy="0 0 0" />
      <geometry>
        <mesh
          filename="package://robotont_description/meshes/Roller113.stl" />
      </geometry>
    </collision>
  </link>
  <joint
    name="Roller113"
    type="continuous">
    <origin
      xyz="-0.0345981954807624 -0.0275911401992594 -0.0298081468021298"
      rpy="0.915756259459614 -1.38777878078145E-17 -0.897597901025655" />
    <parent
      link="Omniwheel1" />
    <child
      link="Roller113" />
    <axis
      xyz="-1 0 0" />
  </joint>
  <link
    name="Roller114">
    <inertial>
      <origin
        xyz="2.41329541877944E-07 0.0275000932715018 2.95936314148593E-07"
        rpy="0 0 0" />
      <mass
        value="0.00222804854629662" />
      <inertia
        ixx="6.29222354445902E-08"
        ixy="4.15895422661478E-13"
        ixz="3.74069132255075E-12"
        iyy="8.63037292804101E-08"
        iyz="6.82637138949575E-13"
        izz="8.63133354079715E-08" />
    </inertial>
    <visual>
      <origin
        xyz="0 0 0"
        rpy="0 0 0" />
      <geometry>
        <mesh
          filename="package://robotont_description/meshes/Roller114.stl" />
      </geometry>
      <material
        name="">
        <color
          rgba="0.792156862745098 0.819607843137255 0.933333333333333 1" />
      </material>
    </visual>
    <collision>
      <origin
        xyz="0 0 0"
        rpy="0 0 0" />
      <geometry>
        <mesh
          filename="package://robotont_description/meshes/Roller114.stl" />
      </geometry>
    </collision>
  </link>
  <joint
    name="Roller114"
    type="continuous">
    <origin
      xyz="-0.0431432440899404 0.00984716392755047 -0.0298081468021298"
      rpy="0.915756259459612 1.38777878078145E-15 -1.79519580205131" />
    <parent
      link="Omniwheel1" />
    <child
      link="Roller114" />
    <axis
      xyz="-1 0 0" />
  </joint>
  <link
    name="Omniwheel2">
    <inertial>
      <origin
        xyz="5.41214934673961E-08 6.17219029941385E-07 -9.69348378787593E-08"
        rpy="0 0 0" />
      <mass
        value="0.022435522293739" />
      <inertia
        ixx="5.90693742137527E-06"
        ixy="2.47313013684889E-10"
        ixz="4.42244946485018E-11"
        iyy="5.90478806903386E-06"
        iyz="1.77564416488955E-10"
        izz="1.03011780721015E-05" />
    </inertial>
    <visual>
      <origin
        xyz="0 0 0"
        rpy="0 0 0" />
      <geometry>
        <mesh
          filename="package://robotont_description/meshes/Omniwheel2.stl" />
      </geometry>
      <material
        name="">
        <color
          rgba="0.792156862745098 0.819607843137255 0.933333333333333 1" />
      </material>
    </visual>
    <collision>
      <origin
        xyz="0 0 0"
        rpy="0 0 0" />
      <geometry>
        <mesh
          filename="package://robotont_description/meshes/Omniwheel2.stl" />
      </geometry>
    </collision>
  </link>
  <joint
    name="Axle2"
    type="continuous">
    <origin
      xyz="0.135408219510917 -0.372642772946523 0.182850551353376"
      rpy="1.5707963267949 0.836473203822852 -6.782769887674E-17" />
    <parent
      link="base_link" />
    <child
      link="Omniwheel2" />
    <axis
      xyz="0 0 1" />
  </joint>
  <link
    name="Roller21">
    <inertial>
      <origin
        xyz="2.39231230617087E-07 0.0285492452543115 -0.00227923224553916"
        rpy="0 0 0" />
      <mass
        value="0.00222805815295261" />
      <inertia
        ixx="6.29209085009669E-08"
        ixy="4.69761783081753E-13"
        ixz="3.27613725276463E-12"
        iyy="8.63042438269798E-08"
        iyz="6.68891870860837E-13"
        izz="8.63118579736287E-08" />
    </inertial>
    <visual>
      <origin
        xyz="0 0 0"
        rpy="0 0 0" />
      <geometry>
        <mesh
          filename="package://robotont_description/meshes/Roller21.stl" />
      </geometry>
      <material
        name="">
        <color
          rgba="0.792156862745098 0.819607843137255 0.933333333333333 1" />
      </material>
    </visual>
    <collision>
      <origin
        xyz="0 0 0"
        rpy="0 0 0" />
      <geometry>
        <mesh
          filename="package://robotont_description/meshes/Roller21.stl" />
      </geometry>
    </collision>
  </link>
  <joint
    name="Roller21"
    type="continuous">
    <origin
      xyz="0 0 0"
      rpy="0.362770953244147 2.77555756156289E-16 -7.7715611723761E-16" />
    <parent
      link="Omniwheel2" />
    <child
      link="Roller21" />
    <axis
      xyz="-1 0 0" />
  </joint>
  <link
    name="Roller22">
    <inertial>
      <origin
        xyz="2.42020345930793E-07 0.0285492419156256 -0.00227921151487143"
        rpy="0 0 0" />
      <mass
        value="0.00222805285160954" />
      <inertia
        ixx="6.29216464203706E-08"
        ixy="5.08975567593325E-13"
        ixz="3.52753992737058E-12"
        iyy="8.63039608776602E-08"
        iyz="7.01034929071296E-13"
        izz="8.63126294422173E-08" />
    </inertial>
    <visual>
      <origin
        xyz="0 0 0"
        rpy="0 0 0" />
      <geometry>
        <mesh
          filename="package://robotont_description/meshes/Roller22.stl" />
      </geometry>
      <material
        name="">
        <color
          rgba="0.792156862745098 0.819607843137255 0.933333333333333 1" />
      </material>
    </visual>
    <collision>
      <origin
        xyz="0 0 0"
        rpy="0 0 0" />
      <geometry>
        <mesh
          filename="package://robotont_description/meshes/Roller22.stl" />
      </geometry>
    </collision>
  </link>
  <joint
    name="Roller22"
    type="continuous">
    <origin
      xyz="0 0 0"
      rpy="0.362770953244146 4.09394740330527E-16 -0.897597901025656" />
    <parent
      link="Omniwheel2" />
    <child
      link="Roller22" />
    <axis
      xyz="-1 0 0" />
  </joint>
  <link
    name="Roller23">
    <inertial>
      <origin
        xyz="0.00139954461455832 0.028130109556491 -0.000238900523193253"
        rpy="0 0 0" />
      <mass
        value="0.00222806201419234" />
      <inertia
        ixx="6.29204495017475E-08"
        ixy="5.98083247838729E-13"
        ixz="3.03993784338456E-12"
        iyy="8.63045317982439E-08"
        iyz="7.91963475713671E-13"
        izz="8.63112526500567E-08" />
    </inertial>
    <visual>
      <origin
        xyz="0 0 0"
        rpy="0 0 0" />
      <geometry>
        <mesh
          filename="package://robotont_description/meshes/Roller23.stl" />
      </geometry>
      <material
        name="">
        <color
          rgba="0.792156862745098 0.819607843137255 0.933333333333333 1" />
      </material>
    </visual>
    <collision>
      <origin
        xyz="0 0 0"
        rpy="0 0 0" />
      <geometry>
        <mesh
          filename="package://robotont_description/meshes/Roller23.stl" />
      </geometry>
    </collision>
  </link>
  <joint
    name="Roller23"
    type="continuous">
    <origin
      xyz="0.00139930623033767 0.00111590948159168 -0.00175882060681615"
      rpy="0.362770953244146 2.77555756156289E-17 -1.79519580205131" />
    <parent
      link="Omniwheel2" />
    <child
      link="Roller23" />
    <axis
      xyz="-1 0 0" />
  </joint>
  <link
    name="Roller24">
    <inertial>
      <origin
        xyz="2.42767097126395E-07 0.0285492433557748 -0.00227919764565071"
        rpy="0 0 0" />
      <mass
        value="0.00222804994084183" />
      <inertia
        ixx="6.29221513451656E-08"
        ixy="5.23643012226202E-13"
        ixz="3.63805941760432E-12"
        iyy="8.63039044385424E-08"
        iyz="7.92706205402649E-13"
        izz="8.63130946829685E-08" />
    </inertial>
    <visual>
      <origin
        xyz="0 0 0"
        rpy="0 0 0" />
      <geometry>
        <mesh
          filename="package://robotont_description/meshes/Roller24.stl" />
      </geometry>
      <material
        name="">
        <color
          rgba="0.792156862745098 0.819607843137255 0.933333333333333 1" />
      </material>
    </visual>
    <collision>
      <origin
        xyz="0 0 0"
        rpy="0 0 0" />
      <geometry>
        <mesh
          filename="package://robotont_description/meshes/Roller24.stl" />
      </geometry>
    </collision>
  </link>
  <joint
    name="Roller24"
    type="continuous">
    <origin
      xyz="0 0 0"
      rpy="0.362770953244146 -3.88578058618805E-16 -2.69279370307697" />
    <parent
      link="Omniwheel2" />
    <child
      link="Roller24" />
    <axis
      xyz="-1 0 0" />
  </joint>
  <link
    name="Roller25">
    <inertial>
      <origin
        xyz="0.00139954725395 0.0281301066380969 -0.000238886103590075"
        rpy="0 0 0" />
      <mass
        value="0.00222805817783925" />
      <inertia
        ixx="6.29209839741734E-08"
        ixy="6.14255351837627E-13"
        ixz="3.24188496008181E-12"
        iyy="8.63043028972296E-08"
        iyz="8.02168149355212E-13"
        izz="8.63118239311127E-08" />
    </inertial>
    <visual>
      <origin
        xyz="0 0 0"
        rpy="0 0 0" />
      <geometry>
        <mesh
          filename="package://robotont_description/meshes/Roller25.stl" />
      </geometry>
      <material
        name="">
        <color
          rgba="0.792156862745098 0.819607843137255 0.933333333333333 1" />
      </material>
    </visual>
    <collision>
      <origin
        xyz="0 0 0"
        rpy="0 0 0" />
      <geometry>
        <mesh
          filename="package://robotont_description/meshes/Roller25.stl" />
      </geometry>
    </collision>
  </link>
  <joint
    name="Roller25"
    type="continuous">
    <origin
      xyz="0.000776556371806417 -0.00161253592170063 -0.00175882060681615"
      rpy="0.362770953244146 -2.22044604925031E-16 2.69279370307696" />
    <parent
      link="Omniwheel2" />
    <child
      link="Roller25" />
    <axis
      xyz="1 0 0" />
  </joint>
  <link
    name="Roller26">
    <inertial>
      <origin
        xyz="-0.00174466419565805 0.0295457326520559 -0.000776177090014707"
        rpy="0 0 0" />
      <mass
        value="0.00222805035043754" />
      <inertia
        ixx="6.2922051047112E-08"
        ixy="4.80075886462761E-13"
        ixz="3.63154829738966E-12"
        iyy="8.63038918147997E-08"
        iyz="7.34817301955861E-13"
        izz="8.63130356930959E-08" />
    </inertial>
    <visual>
      <origin
        xyz="0 0 0"
        rpy="0 0 0" />
      <geometry>
        <mesh
          filename="package://robotont_description/meshes/Roller26.stl" />
      </geometry>
      <material
        name="">
        <color
          rgba="0.792156862745098 0.819607843137255 0.933333333333333 1" />
      </material>
    </visual>
    <collision>
      <origin
        xyz="0 0 0"
        rpy="0 0 0" />
      <geometry>
        <mesh
          filename="package://robotont_description/meshes/Roller26.stl" />
      </geometry>
    </collision>
  </link>
  <joint
    name="Roller26"
    type="continuous">
    <origin
      xyz="0 0.00178977984606152 -0.00175882060681615"
      rpy="0.362770953244146 -4.99600361081321E-16 1.7951958020513" />
    <parent
      link="Omniwheel2" />
    <child
      link="Roller26" />
    <axis
      xyz="1 0 0" />
  </joint>
  <link
    name="Roller27">
    <inertial>
      <origin
        xyz="2.41910656506583E-07 0.0285492409560383 -0.00227921692618654"
        rpy="0 0 0" />
      <mass
        value="0.00222805388994341" />
      <inertia
        ixx="6.29215041715564E-08"
        ixy="5.1511790432501E-13"
        ixz="3.48929284304843E-12"
        iyy="8.63039824659597E-08"
        iyz="6.95868778771031E-13"
        izz="8.63124928890956E-08" />
    </inertial>
    <visual>
      <origin
        xyz="0 0 0"
        rpy="0 0 0" />
      <geometry>
        <mesh
          filename="package://robotont_description/meshes/Roller27.stl" />
      </geometry>
      <material
        name="">
        <color
          rgba="0.792156862745098 0.819607843137255 0.933333333333333 1" />
      </material>
    </visual>
    <collision>
      <origin
        xyz="0 0 0"
        rpy="0 0 0" />
      <geometry>
        <mesh
          filename="package://robotont_description/meshes/Roller27.stl" />
      </geometry>
    </collision>
  </link>
  <joint
    name="Roller27"
    type="continuous">
    <origin
      xyz="0 0 0"
      rpy="0.362770953244147 1.31838984174237E-16 0.897597901025644" />
    <parent
      link="Omniwheel2" />
    <child
      link="Roller27" />
    <axis
      xyz="1 0 0" />
  </joint>
  <link
    name="Roller28">
    <inertial>
      <origin
        xyz="2.42606605832529E-07 0.0275000924335609 2.7828585558165E-07"
        rpy="0 0 0" />
      <mass
        value="0.00222805161471968" />
      <inertia
        ixx="6.2921913051322E-08"
        ixy="4.79810706969164E-13"
        ixz="3.5573580096602E-12"
        iyy="8.63039923214094E-08"
        iyz="7.03900475348655E-13"
        izz="8.6312828261175E-08" />
    </inertial>
    <visual>
      <origin
        xyz="0 0 0"
        rpy="0 0 0" />
      <geometry>
        <mesh
          filename="package://robotont_description/meshes/Roller28.stl" />
      </geometry>
      <material
        name="">
        <color
          rgba="0.792156862745098 0.819607843137255 0.933333333333333 1" />
      </material>
    </visual>
    <collision>
      <origin
        xyz="0 0 0"
        rpy="0 0 0" />
      <geometry>
        <mesh
          filename="package://robotont_description/meshes/Roller28.stl" />
      </geometry>
    </collision>
  </link>
  <joint
    name="Roller28"
    type="continuous">
    <origin
      xyz="-0.019201 0.03987 -0.029808"
      rpy="0.91576 -9.992E-16 -2.6928" />
    <parent
      link="Omniwheel2" />
    <child
      link="Roller28" />
    <axis
      xyz="-1 0 0" />
  </joint>
  <link
    name="Roller29">
    <inertial>
      <origin
        xyz="2.4168984830153E-07 0.0275000931092185 2.49129232465783E-07"
        rpy="0 0 0" />
      <mass
        value="0.00222805776818381" />
      <inertia
        ixx="6.2921085288811E-08"
        ixy="5.5274025242219E-13"
        ixz="3.23643035453875E-12"
        iyy="8.63043467493517E-08"
        iyz="7.25997256708255E-13"
        izz="8.63118623575761E-08" />
    </inertial>
    <visual>
      <origin
        xyz="0 0 0"
        rpy="0 0 0" />
      <geometry>
        <mesh
          filename="package://robotont_description/meshes/Roller29.stl" />
      </geometry>
      <material
        name="">
        <color
          rgba="0.792156862745098 0.819607843137255 0.933333333333333 1" />
      </material>
    </visual>
    <collision>
      <origin
        xyz="0 0 0"
        rpy="0 0 0" />
      <geometry>
        <mesh
          filename="package://robotont_description/meshes/Roller29.stl" />
      </geometry>
    </collision>
  </link>
  <joint
    name="Roller29"
    type="continuous">
    <origin
      xyz="0.0192005499375979 0.039870352771377 -0.0298081468021298"
      rpy="0.915756259459612 -8.60422844084496E-16 2.69279370307696" />
    <parent
      link="Omniwheel2" />
    <child
      link="Roller29" />
    <axis
      xyz="1 0 0" />
  </joint>
  <link
    name="Roller210">
    <inertial>
      <origin
        xyz="2.41411929419177E-07 0.0275000929805565 2.73642241810368E-07"
        rpy="0 0 0" />
      <mass
        value="0.00222805296382808" />
      <inertia
        ixx="6.29216525263325E-08"
        ixy="4.56563755025173E-13"
        ixz="3.52110698735614E-12"
        iyy="8.63039822829956E-08"
        iyz="6.6773618140882E-13"
        izz="8.63126436905978E-08" />
    </inertial>
    <visual>
      <origin
        xyz="0 0 0"
        rpy="0 0 0" />
      <geometry>
        <mesh
          filename="package://robotont_description/meshes/Roller210.stl" />
      </geometry>
      <material
        name="">
        <color
          rgba="0.792156862745098 0.819607843137255 0.933333333333333 1" />
      </material>
    </visual>
    <collision>
      <origin
        xyz="0 0 0"
        rpy="0 0 0" />
      <geometry>
        <mesh
          filename="package://robotont_description/meshes/Roller210.stl" />
      </geometry>
    </collision>
  </link>
  <joint
    name="Roller210"
    type="continuous">
    <origin
      xyz="0.0431432440899406 0.00984716392754997 -0.0298081468021298"
      rpy="0.915756259459611 1.38777878078145E-16 1.7951958020513" />
    <parent
      link="Omniwheel2" />
    <child
      link="Roller210" />
    <axis
      xyz="1 0 0" />
  </joint>
  <link
    name="Roller211">
    <inertial>
      <origin
        xyz="2.41250593502329E-07 0.0275000912052295 2.67396127892616E-07"
        rpy="0 0 0" />
      <mass
        value="0.00222805394526054" />
      <inertia
        ixx="6.29214201640515E-08"
        ixy="5.14120182573522E-13"
        ixz="3.51806755765039E-12"
        iyy="8.63039014768047E-08"
        iyz="6.92290007523198E-13"
        izz="8.63124959788257E-08" />
    </inertial>
    <visual>
      <origin
        xyz="0 0 0"
        rpy="0 0 0" />
      <geometry>
        <mesh
          filename="package://robotont_description/meshes/Roller211.stl" />
      </geometry>
      <material
        name="">
        <color
          rgba="0.792156862745098 0.819607843137255 0.933333333333333 1" />
      </material>
    </visual>
    <collision>
      <origin
        xyz="0 0 0"
        rpy="0 0 0" />
      <geometry>
        <mesh
          filename="package://robotont_description/meshes/Roller211.stl" />
      </geometry>
    </collision>
  </link>
  <joint
    name="Roller211"
    type="continuous">
    <origin
      xyz="0.0345981954807621 -0.0275911401992598 -0.0298081468021298"
      rpy="0.915756259459612 -6.86950496486816E-16 0.897597901025644" />
    <parent
      link="Omniwheel2" />
    <child
      link="Roller211" />
    <axis
      xyz="1 0 0" />
  </joint>
  <link
    name="Roller212">
    <inertial>
      <origin
        xyz="2.39488477993266E-07 0.0275000940256989 2.57828610850108E-07"
        rpy="0 0 0" />
      <mass
        value="0.00222805665066196" />
      <inertia
        ixx="6.29210651014639E-08"
        ixy="4.52292954560008E-13"
        ixz="3.37176231637109E-12"
        iyy="8.63040908847963E-08"
        iyz="6.33004143863799E-13"
        izz="8.63121003647034E-08" />
    </inertial>
    <visual>
      <origin
        xyz="0 0 0"
        rpy="0 0 0" />
      <geometry>
        <mesh
          filename="package://robotont_description/meshes/Roller212.stl" />
      </geometry>
      <material
        name="">
        <color
          rgba="0.792156862745098 0.819607843137255 0.933333333333333 1" />
      </material>
    </visual>
    <collision>
      <origin
        xyz="0 0 0"
        rpy="0 0 0" />
      <geometry>
        <mesh
          filename="package://robotont_description/meshes/Roller212.stl" />
      </geometry>
    </collision>
  </link>
  <joint
    name="Roller212"
    type="continuous">
    <origin
      xyz="0 -0.0442527529993359 -0.0298081468021298"
      rpy="0.915756259459612 5.55111512312578E-17 9.43689570931383E-16" />
    <parent
      link="Omniwheel2" />
    <child
      link="Roller212" />
    <axis
      xyz="-1 0 0" />
  </joint>
  <link
    name="Roller213">
    <inertial>
      <origin
        xyz="2.41541505796583E-07 0.0275000915924574 2.70082327280541E-07"
        rpy="0 0 0" />
      <mass
        value="0.00222805342991147" />
      <inertia
        ixx="6.29215392613625E-08"
        ixy="4.75412124663819E-13"
        ixz="3.51422277497264E-12"
        iyy="8.63039504534327E-08"
        iyz="6.52644833539506E-13"
        izz="8.63125575545935E-08" />
    </inertial>
    <visual>
      <origin
        xyz="0 0 0"
        rpy="0 0 0" />
      <geometry>
        <mesh
          filename="package://robotont_description/meshes/Roller213.stl" />
      </geometry>
      <material
        name="">
        <color
          rgba="0.792156862745098 0.819607843137255 0.933333333333333 1" />
      </material>
    </visual>
    <collision>
      <origin
        xyz="0 0 0"
        rpy="0 0 0" />
      <geometry>
        <mesh
          filename="package://robotont_description/meshes/Roller213.stl" />
      </geometry>
    </collision>
  </link>
  <joint
    name="Roller213"
    type="continuous">
    <origin
      xyz="-0.0345981954807624 -0.0275911401992594 -0.0298081468021298"
      rpy="0.915756259459612 -1.1518563880486E-15 -0.897597901025656" />
    <parent
      link="Omniwheel2" />
    <child
      link="Roller213" />
    <axis
      xyz="-1 0 0" />
  </joint>
  <link
    name="Roller214">
    <inertial>
      <origin
        xyz="2.39670415846938E-07 0.0275000953328124 2.39094453402533E-07"
        rpy="0 0 0" />
      <mass
        value="0.00222806047866909" />
      <inertia
        ixx="6.29206975602234E-08"
        ixy="5.35871755260417E-13"
        ixz="3.1010013163998E-12"
        iyy="8.63044839632031E-08"
        iyz="7.13346018582764E-13"
        izz="8.63114745786361E-08" />
    </inertial>
    <visual>
      <origin
        xyz="0 0 0"
        rpy="0 0 0" />
      <geometry>
        <mesh
          filename="package://robotont_description/meshes/Roller214.stl" />
      </geometry>
      <material
        name="">
        <color
          rgba="0.792156862745098 0.819607843137255 0.933333333333333 1" />
      </material>
    </visual>
    <collision>
      <origin
        xyz="0 0 0"
        rpy="0 0 0" />
      <geometry>
        <mesh
          filename="package://robotont_description/meshes/Roller214.stl" />
      </geometry>
    </collision>
  </link>
  <joint
    name="Roller214"
    type="continuous">
    <origin
      xyz="-0.0431432440899405 0.00984716392755047 -0.0298081468021298"
      rpy="0.915756259459611 1.94289029309402E-16 -1.79519580205131" />
    <parent
      link="Omniwheel2" />
    <child
      link="Roller214" />
    <axis
      xyz="-1 0 0" />
  </joint>
  <link
    name="Omniwheel3">
    <inertial>
      <origin
        xyz="5.79729576566379E-08 6.16551263626919E-07 -1.01597076501703E-07"
        rpy="0 0 0" />
      <mass
        value="0.0224355450669598" />
      <inertia
        ixx="5.9069394475215E-06"
        ixy="2.47088915947909E-10"
        ixz="4.46347812849997E-11"
        iyy="5.90479073253165E-06"
        iyz="1.78726246550039E-10"
        izz="1.03011806930321E-05" />
    </inertial>
    <visual>
      <origin
        xyz="0 0 0"
        rpy="0 0 0" />
      <geometry>
        <mesh
          filename="package://robotont_description/meshes/Omniwheel3.stl" />
      </geometry>
      <material
        name="">
        <color
          rgba="0.792156862745098 0.819607843137255 0.933333333333333 1" />
      </material>
    </visual>
    <collision>
      <origin
        xyz="0 0 0"
        rpy="0 0 0" />
      <geometry>
        <mesh
          filename="package://robotont_description/meshes/Omniwheel3.stl" />
      </geometry>
    </collision>
  </link>
  <joint
    name="Axle3"
    type="continuous">
    <origin
      xyz="0.248589957515507 -0.176606252233622 0.182850551353376"
      rpy="1.5707963267949 0.836473203822853 2.0943951023932" />
    <parent
      link="base_link" />
    <child
      link="Omniwheel3" />
    <axis
      xyz="0 0 1" />
  </joint>
  <link
    name="Roller31">
    <inertial>
      <origin
        xyz="2.39024965265067E-07 0.028549243246719 -0.00227924567075752"
        rpy="0 0 0" />
      <mass
        value="0.00222806045765569" />
      <inertia
        ixx="6.29205719908983E-08"
        ixy="5.39748648515095E-13"
        ixz="3.1663924775527E-12"
        iyy="8.63043162349114E-08"
        iyz="6.86996034460368E-13"
        izz="8.63114980991219E-08" />
    </inertial>
    <visual>
      <origin
        xyz="0 0 0"
        rpy="0 0 0" />
      <geometry>
        <mesh
          filename="package://robotont_description/meshes/Roller31.stl" />
      </geometry>
      <material
        name="">
        <color
          rgba="0.792156862745098 0.819607843137255 0.933333333333333 1" />
      </material>
    </visual>
    <collision>
      <origin
        xyz="0 0 0"
        rpy="0 0 0" />
      <geometry>
        <mesh
          filename="package://robotont_description/meshes/Roller31.stl" />
      </geometry>
    </collision>
  </link>
  <joint
    name="Roller31"
    type="continuous">
    <origin
      xyz="0 0 0"
      rpy="0.362770953244145 2.22044604925031E-16 7.21644966006352E-16" />
    <parent
      link="Omniwheel3" />
    <child
      link="Roller31" />
    <axis
      xyz="-1 0 0" />
  </joint>
  <link
    name="Roller32">
    <inertial>
      <origin
        xyz="2.42653946908034E-07 0.0285492426083572 -0.00227920779553961"
        rpy="0 0 0" />
      <mass
        value="0.00222805197029901" />
      <inertia
        ixx="6.29218452079995E-08"
        ixy="5.45123117062778E-13"
        ixz="3.55054054636394E-12"
        iyy="8.63039777826319E-08"
        iyz="7.78362036349722E-13"
        izz="8.63127770316306E-08" />
    </inertial>
    <visual>
      <origin
        xyz="0 0 0"
        rpy="0 0 0" />
      <geometry>
        <mesh
          filename="package://robotont_description/meshes/Roller32.stl" />
      </geometry>
      <material
        name="">
        <color
          rgba="0.792156862745098 0.819607843137255 0.933333333333333 1" />
      </material>
    </visual>
    <collision>
      <origin
        xyz="0 0 0"
        rpy="0 0 0" />
      <geometry>
        <mesh
          filename="package://robotont_description/meshes/Roller32.stl" />
      </geometry>
    </collision>
  </link>
  <joint
    name="Roller32"
    type="continuous">
    <origin
      xyz="0 0 0"
      rpy="0.362770953244145 -1.33226762955019E-15 -0.897597901025657" />
    <parent
      link="Omniwheel3" />
    <child
      link="Roller32" />
    <axis
      xyz="-1 0 0" />
  </joint>
  <link
    name="Roller33">
    <inertial>
      <origin
        xyz="0.001399542993819 0.0281301104034433 -0.000238899376431623"
        rpy="0 0 0" />
      <mass
        value="0.00222806223295386" />
      <inertia
        ixx="6.29203203205011E-08"
        ixy="5.163939449825E-13"
        ixz="3.08720173654304E-12"
        iyy="8.63044313430891E-08"
        iyz="7.26077235840499E-13"
        izz="8.63112607282497E-08" />
    </inertial>
    <visual>
      <origin
        xyz="0 0 0"
        rpy="0 0 0" />
      <geometry>
        <mesh
          filename="package://robotont_description/meshes/Roller33.stl" />
      </geometry>
      <material
        name="">
        <color
          rgba="0.792156862745098 0.819607843137255 0.933333333333333 1" />
      </material>
    </visual>
    <collision>
      <origin
        xyz="0 0 0"
        rpy="0 0 0" />
      <geometry>
        <mesh
          filename="package://robotont_description/meshes/Roller33.stl" />
      </geometry>
    </collision>
  </link>
  <joint
    name="Roller33"
    type="continuous">
    <origin
      xyz="0.00139930623033768 0.00111590948159165 -0.00175882060681615"
      rpy="0.362770953244146 4.44089209850063E-16 -1.79519580205131" />
    <parent
      link="Omniwheel3" />
    <child
      link="Roller33" />
    <axis
      xyz="1 0 0" />
  </joint>
  <link
    name="Roller34">
    <inertial>
      <origin
        xyz="0.00139954883347837 0.0281301037590076 -0.000238837971586359"
        rpy="0 0 0" />
      <mass
        value="0.00222804787412911" />
      <inertia
        ixx="6.29223291418879E-08"
        ixy="4.50079557873077E-13"
        ixz="3.76817390372401E-12"
        iyy="8.63037054622645E-08"
        iyz="6.84934801923954E-13"
        izz="8.63133854599778E-08" />
    </inertial>
    <visual>
      <origin
        xyz="0 0 0"
        rpy="0 0 0" />
      <geometry>
        <mesh
          filename="package://robotont_description/meshes/Roller34.stl" />
      </geometry>
      <material
        name="">
        <color
          rgba="0.792156862745098 0.819607843137255 0.933333333333333 1" />
      </material>
    </visual>
    <collision>
      <origin
        xyz="0 0 0"
        rpy="0 0 0" />
      <geometry>
        <mesh
          filename="package://robotont_description/meshes/Roller34.stl" />
      </geometry>
    </collision>
  </link>
  <joint
    name="Roller34"
    type="continuous">
    <origin
      xyz="0.0017449 -0.00039826 -0.0017588"
      rpy="0.36277 4.996E-16 -2.6928" />
    <parent
      link="Omniwheel3" />
    <child
      link="Roller34" />
    <axis
      xyz="1 0 0" />
  </joint>
  <link
    name="Roller35">
    <inertial>
      <origin
        xyz="0.00139954734808501 0.028130106094081 -0.000238887509821928"
        rpy="0 0 0" />
      <mass
        value="0.00222805834897051" />
      <inertia
        ixx="6.29209808061219E-08"
        ixy="6.20107857204978E-13"
        ixz="3.22743147662919E-12"
        iyy="8.63043130196061E-08"
        iyz="7.99320961575653E-13"
        izz="8.63118107971376E-08" />
    </inertial>
    <visual>
      <origin
        xyz="0 0 0"
        rpy="0 0 0" />
      <geometry>
        <mesh
          filename="package://robotont_description/meshes/Roller35.stl" />
      </geometry>
      <material
        name="">
        <color
          rgba="0.792156862745098 0.819607843137255 0.933333333333333 1" />
      </material>
    </visual>
    <collision>
      <origin
        xyz="0 0 0"
        rpy="0 0 0" />
      <geometry>
        <mesh
          filename="package://robotont_description/meshes/Roller35.stl" />
      </geometry>
    </collision>
  </link>
  <joint
    name="Roller35"
    type="continuous">
    <origin
      xyz="0.000776556371806403 -0.00161253592170063 -0.00175882060681615"
      rpy="0.362770953244146 7.07767178198537E-16 2.69279370307696" />
    <parent
      link="Omniwheel3" />
    <child
      link="Roller35" />
    <axis
      xyz="1 0 0" />
  </joint>
  <link
    name="Roller36">
    <inertial>
      <origin
        xyz="2.42207623679658E-07 0.028549242416272 -0.0022791811800825"
        rpy="0 0 0" />
      <mass
        value="0.00222804656940515" />
      <inertia
        ixx="6.29225307529969E-08"
        ixy="4.72297121744004E-13"
        ixz="3.8156291349228E-12"
        iyy="8.6303644029232E-08"
        iyz="7.44531724686731E-13"
        izz="8.63136149592252E-08" />
    </inertial>
    <visual>
      <origin
        xyz="0 0 0"
        rpy="0 0 0" />
      <geometry>
        <mesh
          filename="package://robotont_description/meshes/Roller36.stl" />
      </geometry>
      <material
        name="">
        <color
          rgba="0.792156862745098 0.819607843137255 0.933333333333333 1" />
      </material>
    </visual>
    <collision>
      <origin
        xyz="0 0 0"
        rpy="0 0 0" />
      <geometry>
        <mesh
          filename="package://robotont_description/meshes/Roller36.stl" />
      </geometry>
    </collision>
  </link>
  <joint
    name="Roller36"
    type="continuous">
    <origin
      xyz="0 0 0"
      rpy="0.362770953244147 -6.66133814775094E-16 1.7951958020513" />
    <parent
      link="Omniwheel3" />
    <child
      link="Roller36" />
    <axis
      xyz="1 0 0" />
  </joint>
  <link
    name="Roller37">
    <inertial>
      <origin
        xyz="2.40113111504847E-07 0.0285492423942931 -0.00227920873453714"
        rpy="0 0 0" />
      <mass
        value="0.00222805304022832" />
      <inertia
        ixx="6.29215167317484E-08"
        ixy="4.43270220436539E-13"
        ixz="3.58728488367006E-12"
        iyy="8.63038097226508E-08"
        iyz="6.68639879358085E-13"
        izz="8.63126908515853E-08" />
    </inertial>
    <visual>
      <origin
        xyz="0 0 0"
        rpy="0 0 0" />
      <geometry>
        <mesh
          filename="package://robotont_description/meshes/Roller37.stl" />
      </geometry>
      <material
        name="">
        <color
          rgba="0.792156862745098 0.819607843137255 0.933333333333333 1" />
      </material>
    </visual>
    <collision>
      <origin
        xyz="0 0 0"
        rpy="0 0 0" />
      <geometry>
        <mesh
          filename="package://robotont_description/meshes/Roller37.stl" />
      </geometry>
    </collision>
  </link>
  <joint
    name="Roller37"
    type="continuous">
    <origin
      xyz="0 0 0"
      rpy="0.362770953244145 9.99200722162641E-16 0.897597901025646" />
    <parent
      link="Omniwheel3" />
    <child
      link="Roller37" />
    <axis
      xyz="-1 0 0" />
  </joint>
  <link
    name="Roller38">
    <inertial>
      <origin
        xyz="2.39097279530753E-07 0.0275000930103924 2.52646631782039E-07"
        rpy="0 0 0" />
      <mass
        value="0.00222805753419375" />
      <inertia
        ixx="6.292085918112E-08"
        ixy="5.03858091210404E-13"
        ixz="3.36566616474535E-12"
        iyy="8.63040348496227E-08"
        iyz="6.63524252772352E-13"
        izz="8.63119631620465E-08" />
    </inertial>
    <visual>
      <origin
        xyz="0 0 0"
        rpy="0 0 0" />
      <geometry>
        <mesh
          filename="package://robotont_description/meshes/Roller38.stl" />
      </geometry>
      <material
        name="">
        <color
          rgba="0.792156862745098 0.819607843137255 0.933333333333333 1" />
      </material>
    </visual>
    <collision>
      <origin
        xyz="0 0 0"
        rpy="0 0 0" />
      <geometry>
        <mesh
          filename="package://robotont_description/meshes/Roller38.stl" />
      </geometry>
    </collision>
  </link>
  <joint
    name="Roller38"
    type="continuous">
    <origin
      xyz="-0.0192005499375975 0.0398703527713771 -0.0298081468021298"
      rpy="0.915756259459614 -3.33066907387547E-16 -2.69279370307697" />
    <parent
      link="Omniwheel3" />
    <child
      link="Roller38" />
    <axis
      xyz="1 0 0" />
  </joint>
  <link
    name="Roller39">
    <inertial>
      <origin
        xyz="2.41632620079368E-07 0.027500093192755 2.46831294653527E-07"
        rpy="0 0 0" />
      <mass
        value="0.00222805824992304" />
      <inertia
        ixx="6.29210279519415E-08"
        ixy="5.77472466845125E-13"
        ixz="3.21118063029334E-12"
        iyy="8.63043752824002E-08"
        iyz="7.54787576425387E-13"
        izz="8.63117920443888E-08" />
    </inertial>
    <visual>
      <origin
        xyz="0 0 0"
        rpy="0 0 0" />
      <geometry>
        <mesh
          filename="package://robotont_description/meshes/Roller39.stl" />
      </geometry>
      <material
        name="">
        <color
          rgba="0.792156862745098 0.819607843137255 0.933333333333333 1" />
      </material>
    </visual>
    <collision>
      <origin
        xyz="0 0 0"
        rpy="0 0 0" />
      <geometry>
        <mesh
          filename="package://robotont_description/meshes/Roller39.stl" />
      </geometry>
    </collision>
  </link>
  <joint
    name="Roller39"
    type="continuous">
    <origin
      xyz="0.0192005499375978 0.0398703527713769 -0.0298081468021298"
      rpy="0.915756259459612 -4.16333634234434E-16 2.69279370307696" />
    <parent
      link="Omniwheel3" />
    <child
      link="Roller39" />
    <axis
      xyz="1 0 0" />
  </joint>
  <link
    name="Roller310">
    <inertial>
      <origin
        xyz="2.43395189961082E-07 0.0275000913783518 3.13233187554385E-07"
        rpy="0 0 0" />
      <mass
        value="0.00222804374997192" />
      <inertia
        ixx="6.2923074776917E-08"
        ixy="4.46641742862579E-13"
        ixz="3.88658774789985E-12"
        iyy="8.63036712718867E-08"
        iyz="7.33900542171251E-13"
        izz="8.63140162418859E-08" />
    </inertial>
    <visual>
      <origin
        xyz="0 0 0"
        rpy="0 0 0" />
      <geometry>
        <mesh
          filename="package://robotont_description/meshes/Roller310.stl" />
      </geometry>
      <material
        name="">
        <color
          rgba="0.792156862745098 0.819607843137255 0.933333333333333 1" />
      </material>
    </visual>
    <collision>
      <origin
        xyz="0 0 0"
        rpy="0 0 0" />
      <geometry>
        <mesh
          filename="package://robotont_description/meshes/Roller310.stl" />
      </geometry>
    </collision>
  </link>
  <joint
    name="Roller310"
    type="continuous">
    <origin
      xyz="0.0431432440899405 0.00984716392754993 -0.0298081468021298"
      rpy="0.91575625945961 8.32667268468867E-17 1.7951958020513" />
    <parent
      link="Omniwheel3" />
    <child
      link="Roller310" />
    <axis
      xyz="1 0 0" />
  </joint>
  <link
    name="Roller311">
    <inertial>
      <origin
        xyz="2.39520214606603E-07 0.027500094090709 2.78836239597791E-07"
        rpy="0 0 0" />
      <mass
        value="0.00222805243059925" />
      <inertia
        ixx="6.2921517199345E-08"
        ixy="5.20238553302207E-13"
        ixz="3.6502932912151E-12"
        iyy="8.63036766070656E-08"
        iyz="7.83985594710125E-13"
        izz="8.63128051851166E-08" />
    </inertial>
    <visual>
      <origin
        xyz="0 0 0"
        rpy="0 0 0" />
      <geometry>
        <mesh
          filename="package://robotont_description/meshes/Roller311.stl" />
      </geometry>
      <material
        name="">
        <color
          rgba="0.792156862745098 0.819607843137255 0.933333333333333 1" />
      </material>
    </visual>
    <collision>
      <origin
        xyz="0 0 0"
        rpy="0 0 0" />
      <geometry>
        <mesh
          filename="package://robotont_description/meshes/Roller311.stl" />
      </geometry>
    </collision>
  </link>
  <joint
    name="Roller311"
    type="continuous">
    <origin
      xyz="0.034598195480762 -0.0275911401992598 -0.0298081468021298"
      rpy="0.915756259459612 1.33226762955019E-15 0.897597901025644" />
    <parent
      link="Omniwheel3" />
    <child
      link="Roller311" />
    <axis
      xyz="-1 0 0" />
  </joint>
  <link
    name="Roller312">
    <inertial>
      <origin
        xyz="2.40079755353673E-07 0.0275000952624256 2.46051895802513E-07"
        rpy="0 0 0" />
      <mass
        value="0.00222805909473683" />
      <inertia
        ixx="6.29208677635619E-08"
        ixy="4.81038307870187E-13"
        ixz="3.18158805714489E-12"
        iyy="8.63044087601721E-08"
        iyz="6.6968413793832E-13"
        izz="8.6311673152322E-08" />
    </inertial>
    <visual>
      <origin
        xyz="0 0 0"
        rpy="0 0 0" />
      <geometry>
        <mesh
          filename="package://robotont_description/meshes/Roller312.stl" />
      </geometry>
      <material
        name="">
        <color
          rgba="0.792156862745098 0.819607843137255 0.933333333333333 1" />
      </material>
    </visual>
    <collision>
      <origin
        xyz="0 0 0"
        rpy="0 0 0" />
      <geometry>
        <mesh
          filename="package://robotont_description/meshes/Roller312.stl" />
      </geometry>
    </collision>
  </link>
  <joint
    name="Roller312"
    type="continuous">
    <origin
      xyz="0 -0.044252752999336 -0.0298081468021297"
      rpy="0.915756259459611 5.55111512312578E-16 1.22124532708767E-15" />
    <parent
      link="Omniwheel3" />
    <child
      link="Roller312" />
    <axis
      xyz="-1 0 0" />
  </joint>
  <link
    name="Roller313">
    <inertial>
      <origin
        xyz="2.4234265247336E-07 -2.42707048903057E-07 1.5123638988368E-07"
        rpy="0 0 0" />
      <mass
        value="0.00222805294277978" />
      <inertia
        ixx="6.29216704053611E-08"
        ixy="-3.29692709819246E-12"
        ixz="1.28141627550218E-12"
        iyy="8.63118615041975E-08"
        iyz="-2.51502553535106E-12"
        izz="8.63047502007656E-08" />
    </inertial>
    <visual>
      <origin
        xyz="0 0 0"
        rpy="0 0 0" />
      <geometry>
        <mesh
          filename="package://robotont_description/meshes/Roller313.stl" />
      </geometry>
      <material
        name="">
        <color
          rgba="0.792156862745098 0.819607843137255 0.933333333333333 1" />
      </material>
    </visual>
    <collision>
      <origin
        xyz="0 0 0"
        rpy="0 0 0" />
      <geometry>
        <mesh
          filename="package://robotont_description/meshes/Roller313.stl" />
      </geometry>
    </collision>
  </link>
  <joint
    name="Roller313"
    type="continuous">
    <origin
      xyz="-0.0215003657678708 -0.0171459695511152 -0.00799999999999999"
      rpy="-0.422962332618568 -4.16333634234434E-17 -0.897597901025655" />
    <parent
      link="Omniwheel3" />
    <child
      link="Roller313" />
    <axis
      xyz="-1 0 0" />
  </joint>
  <link
    name="Roller314">
    <inertial>
      <origin
        xyz="2.38878043873347E-07 0.0275000962700117 2.48782507150658E-07"
        rpy="0 0 0" />
      <mass
        value="0.00222805889351307" />
      <inertia
        ixx="6.29208105587859E-08"
        ixy="4.93887677877812E-13"
        ixz="3.24093501433763E-12"
        iyy="8.63042910771101E-08"
        iyz="7.09354777239653E-13"
        izz="8.63117472226975E-08" />
    </inertial>
    <visual>
      <origin
        xyz="0 0 0"
        rpy="0 0 0" />
      <geometry>
        <mesh
          filename="package://robotont_description/meshes/Roller314.stl" />
      </geometry>
      <material
        name="">
        <color
          rgba="0.792156862745098 0.819607843137255 0.933333333333333 1" />
      </material>
    </visual>
    <collision>
      <origin
        xyz="0 0 0"
        rpy="0 0 0" />
      <geometry>
        <mesh
          filename="package://robotont_description/meshes/Roller314.stl" />
      </geometry>
    </collision>
  </link>
  <joint
    name="Roller314"
    type="continuous">
    <origin
      xyz="-0.0431432440899405 0.0098471639275504 -0.0298081468021298"
      rpy="0.915756259459611 2.77555756156289E-16 -1.79519580205131" />
    <parent
      link="Omniwheel3" />
    <child
      link="Roller314" />
    <axis
      xyz="1 0 0" />
  </joint>
</robot>